Workbook

Sheet 入力
C1: 3A | F1: 3B | I1: 2A | M1: 2B | Q1: 2C | U1: 1A | Y1: 1B | AC1: 1C | AG1: 1D | AK1: 1E | AO1: 攻城戦
B2: 日 | C2: デルニール農場 | I2: 略奪の森 | M2: 忘却の地 | U2: ナーガ沼地 | Y2: 旧ダンデリオン | AC2: 捨てられた地 | AG2: ベア川下流 | AK2: アルティノ入り口 | AO2: カルフェオン | AR2: バレンシア
B3: 月 | C3: ルツム族駐屯地 | F3: アト農場 | I3: ベリア農場地帯 | M3: ギュントの丘 | Q3: 高原地帯 | U3: 隠遁の森 | Y3: エワズの丘 | AC3: 廃城跡入り口 | AG3: カイア渡し場 | AK3: カズラ農場
B4: 木 | C4: 北部大農場 | I4: トロル防御基地 | M4: 隠された修道院 | Q4: マルニの第2実験場 | U4: アグリス平原 | Y4: リンチ農場廃墟 | AC4: ブレディー砦 | AG4: エントの森 | AK4: クリオ村
B5: 金 | C5: アグリス祭壇 | I5: ナーガ抽出場 | M5: オークキャンプ | U5: 北部採石場 | Y5: ハーピーの絶壁 | AC5: ブリの森 | AG5: マンシャの森の奥 | AK5: 廃鉄鉱山採掘場
A6: 45887 | C6: 勝利ギルド | D6: 対戦 | E6: 宴会 | F6: 勝利ギルド | G6: 対戦 | H6: 宴会 | I6: 勝利ギルド | J6: 対戦 | K6: 統一 | L6: 宴会 | M6: 勝利ギルド | N6: 対戦 | O6: 統一 | P6: 宴会 | Q6: 勝利ギルド | R6: 対戦 | S6: 統一 | T6: 宴会 | U6: 勝利ギルド | V6: 対戦 | W6: 統一 | X6: 宴会 | Y6: 勝利ギルド | Z6: 対戦 | AA6: 統一 | AB6: 宴会 | AC6: 勝利ギルド | AD6: 対戦 | AE6: 統一 | AF6: 宴会 | AG6: 勝利ギルド | AH6: 対戦 | AI6: 統一 | AJ6: 宴会 | AK6: 勝利ギルド | AL6: 対戦 | AM6: 統一 | AN6: 宴会 | AO6: 勝利 | AP6: 攻城1 | AQ6: 攻城2 | AR6: 勝利 | AS6: 攻城1 | AT6: 攻城2
A7: =A6+1 -> 45888 | B7: 火
A8: =A7+1 -> 45889 | B8: 水
A9: =A8+1 -> 45890 | B9: 木 | C9: RaиkSS | D9: 4 | E9: 宴会 | I9: AlmaVivaJP | J9: 4 | K9: - | L9: - | M9: PONYTAIL | N9: 5 | O9: - | P9: - | Q9: TheUniverse | R9: 2 | S9: - | T9: - | U9: C0BRA | V9: 5 | W9: 統一 | X9: 宴会 | Y9: Anino | Z9: 2 | AA9: - | AB9: - | AC9: SkyCastle | AD9: 3 | AE9: - | AF9: - | AG9: TipsyTavern | AH9: 3 | AI9: - | AJ9: - | AK9: UnityJP | AL9: 3 | AM9: - | AN9: -
A10: =A9+1 -> 45891 | B10: 金 | C10: PONYTAIL | D10: 5 | E10: - | I10: MystSA | J10: 2 | K10: - | L10: - | M10: Anino | N10: 3 | O10: - | P10: - | U10: ひよこ座流星群 | V10: 5 | W10: - | X10: - | Y10: REGENCY彡 | Z10: 3 | AA10: - | AB10: - | AC10: Kopitiam | AD10: 3 | AE10: - | AF10: - | AG10: Maverickz | AH10: 3 | AI10: - | AJ10: - | AK10: ーArchー | AL10: 3 | AM10: - | AN10: 宴会
A11: =A10+1 -> 45892 | B11: 土 | AO11: PONYTAIL | AP11: MystSA | AQ11: AlmaVivaJP | AR11: RaиkSS | AS11: Anino | AT11: TheUniverse
A12: =A11+1 -> 45893 | B12: 日 | C12: MystSA | E12: - | I12: 氣噗噗讓玻璃心碎一地 | K12: - | L12: - | M12: AlmaVivaJP | O12: - | P12: - | U12: 一DEFlANCE | W12: 統一 | X12: - | Y12: シェイド | AA12: 統一 | AB12: - | AC12: PokemonGo | AE12: - | AF12: 宴会 | AG12: UnityJP | AI12: - | AJ12: - | AK12: ーArchー | AM12: - | AN12: -
A13: =A12+1 -> 45894 | B13: 月 | C13: TRAITORs | E13: - | F13: ーリベリオンー | H13: - | I13: PokemonGo | K13: - | L13: 宴会 | M13: VainqueurJP | O13: - | P13: - | Q13: 殺戮THM | S13: - | T13: - | U13: Restart | W13: - | X13: - | Y13: 一惡人谷一 | AA13: 統一 | AB13: 宴会 | AC13: DoraemonSA | AE13: - | AF13: - | AG13: シェイド | AI13: - | AJ13: 宴会 | AK13: SkyCastle | AM13: - | AN13: -
A14: =A13+1 -> 45895 | B14: 火
A15: =A14+1 -> 45896 | B15: 水
A16: =A15+1 -> 45897 | B16: 木 | C16: MystSA | E16: - | I16: 黒の太陽 | K16: - | L16: - | M16: 桜吹雪 | O16: - | P16: 宴会 | Q16: TheUniverse | S16: - | T16: - | U16: Revenant | W16: - | X16: - | Y16: xAEGISx | AA16: 統一 | AB16: - | AC16: SkyCastle | AE16: - | AF16: 宴会 | AG16: LeLien | AI16: - | AJ16: - | AK16: 海尼根飲酒俱樂部 | AM16: - | AN16: 宴会
A17: =A16+1 -> 45898 | B17: 金 | C17: LeLien | E17: 宴会 | I17: MÏRÃGË | K17: 統一 | L17: - | M17: 沙漠黑鷹 | O17: - | P17: - | U17: TheEnd | W17: - | X17: 宴会 | Y17: シェイド | AA17: - | AB17: - | AC17: M三OW | AE17: 統一 | AF17: - | AG17: Maverickz | AI17: 統一 | AJ17: - | AK17: 一DEFlANCE | AM17: 統一 | AN17: -
A18: =A17+1 -> 45899 | B18: 土 | AO18: AlmaVivaJP | AR18: TRAITORs
A19: =A18+1 -> 45900 | B19: 日 | C19: ーリベリオンー | E19: 宴会 | I19: 氣噗噗讓玻璃心碎一地 | K19: - | L19: 宴会 | M19: PONYTAIL | O19: - | P19: - | U19: SkyCastle | W19: - | X19: 宴会 | Y19: PhoenixJP | AA19: - | AB19: - | AC19: オアシスステップ | AE19: - | AF19: - | AG19: ouтcasт | AI19: 統一 | AJ19: - | AK19: ーArchー | AM19: 統一 | AN19: -
A20: =A19+1 -> 45901 | B20: 月 | C20: 廣寒宮 | E20: 宴会 | F20: LeLien | H20: 宴会 | I20: 氣噗噗讓玻璃心碎一地 | K20: - | L20: - | M20: VainqueurJP | O20: - | P20: - | Q20: RaиkSS | S20: - | T20: - | U20: Relax | W20: - | X20: - | Y20: 花落微雨醉紅塵 | AA20: - | AB20: - | AC20: xAEGISx | AE20: - | AF20: - | AG20: シェイド | AI20: - | AJ20: - | AK20: Bagaиі | AM20: 統一 | AN20: 宴会
A21: =A20+1 -> 45902 | B21: 火
A22: =A21+1 -> 45903 | B22: 水
A23: =A22+1 -> 45904 | B23: 木 | C23: MystSA | E23: - | I23: xAEGISx | K23: 統一 | L23: 宴会 | M23: 雪狼族 | O23: - | P23: - | Q23: PhoenixJP | S23: - | T23: - | U23: βυsнỉȉdo家族 | W23: 統一 | X23: - | Y23: 一惡人谷一 | AA23: - | AB23: 宴会 | AC23: ねこ | AE23: 統一 | AF23: - | AG23: SkyCastle | AI23: - | AJ23: 宴会 | AK23: Maverickz | AM23: - | AN23: -
A24: =A23+1 -> 45905 | B24: 金 | C24: LeLien | E24: - | I24: Döraêmön | K24: - | L24: 宴会 | M24: ・殺戮・ | O24: - | P24: - | U24: TheEnd | W24: 統一 | X24: - | Y24: オアシスステップ | AA24: - | AB24: 宴会 | AC24: ーEspoirー | AE24: - | AF24: 宴会 | AG24: RëBîrth | AI24: - | AJ24: - | AK24: 一DEFlANCE | AM24: - | AN24: -
A25: =A24+1 -> 45906 | B25: 土
A26: =A25+1 -> 45907 | B26: 日 | C26: xAEGISx | E26: - | I26: PokemonGo | K26: - | L26: - | M26: RaиkSS | O26: - | P26: 宴会 | U26: 亗Luxúria亗 | W26: 統一 | X26: - | Y26: PhoenixJP | AA26: 統一 | AB26: - | AC26: オアシスステップ | AE26: 統一 | AF26: - | AG26: Restart | AI26: - | AJ26: - | AK26: UnityJP | AM26: - | AN26: 宴会
A27: =A26+1 -> 45908 | B27: 月 | C27: 雪狼族 | E27: 宴会 | F27: PhoenixJP | H27: - | I27: 氣噗噗讓玻璃心碎一地 | K27: - | L27: 宴会 | M27: AlmaVivaJP | O27: - | P27: - | Q27: Maverickz | S27: - | T27: - | U27: Relax | W27: - | X27: - | Y27: 花落微雨醉紅塵 | AA27: 統一 | AB27: - | AC27: 天機 | AE27: - | AF27: 宴会 | AG27: シェイド | AI27: - | AJ27: 宴会 | AK27: ーArchー | AM27: - | AN27: -
A28: =A27+1 -> 45909 | B28: 火
A29: =A28+1 -> 45910 | B29: 水
A30: =A29+1 -> 45911 | B30: 木 | C30: MystSA | E30: 宴会 | I30: ー麒麟ー | K30: - | L30: - | M30: ・殺戮・ | O30: - | P30: - | Q30: Иouver | S30: - | T30: 宴会 | U30: 亗Luxúria亗 | W30: - | X30: 宴会 | Y30: Anino | AA30: 統一 | AB30: - | AC30: 沙漠黑鷹 | AE30: - | AF30: - | AI30: - | AJ30: - | AK30: シェイド | AM30: - | AN30: -
A31: =A30+1 -> 45912 | B31: 金 | C31: ーリベリオンー | E31: 宴会 | I31: VainqueurJP | K31: - | L31: - | M31: SkyCastle | O31: - | P31: - | U31: 桜吹雪 | W31: - | X31: - | Y31: 黒の太陽 | AA31: - | AB31: - | AC31: Kopitiam | AE31: 統一 | AF31: - | AG31: RëBîrth | AI31: 統一 | AJ31: 宴会 | AK31: 一DEFlANCE | AM31: 統一 | AN31: 宴会
A32: =A31+1 -> 45913 | B32: 土
A33: =A32+1 -> 45914 | B33: 日 | C33: 沙漠黑鷹 | E33: 宴会 | I33: PokemonGo | K33: - | L33: 宴会 | M33: RaиkSS | O33: - | P33: - | U33: βυsнỉȉdo家族 | W33: 統一 | X33: - | Y33: ーArchー | AA33: 統一 | AB33: - | AC33: Anino | AE33: - | AF33: 宴会 | AG33: 磯野家 | AI33: - | AJ33: - | AK33: MÏRÃGË | AM33: - | AN33: -
A34: =A33+1 -> 45915 | B34: 月 | C34: ・殺戮・ | E34: 宴会 | F34: LeLien | I34: PONYTAIL | K34: - | L34: 宴会 | M34: ーArchー | O34: - | P34: - | Q34: Maverickz | S34: 統一 | T34: - | U34: ZirconiA | W34: - | X34: - | Y34: TheUniverse | AA34: - | AB34: - | AC34: xAEGISx | AE34: 統一 | AF34: 宴会 | AG34: 一惡人谷一 | AI34: - | AJ34: 宴会 | AK34: 彡MukBANG彡 | AM34: 統一 | AN34: -
A35: =A34+1 -> 45916 | B35: 火
A36: =A35+1 -> 45917 | B36: 水
A37: =A36+1 -> 45918 | B37: 木 | C37: PONYTAIL | E37: - | I37: ー麒麟ー | K37: - | L37: - | M37: 桜吹雪 | O37: - | P37: - | Q37: 雪狼族 | S37: - | T37: - | U37: 亗Luxúria亗 | W37: - | X37: - | Y37: 心晴 | AA37: - | AB37: - | AC37: TheUniverse | AE37: - | AF37: 宴会 | AG37: TipsyTavern | AI37: 統一 | AJ37: - | AK37: Döraêmön | AM37: 統一 | AN37: 宴会
A38: =A37+1 -> 45919 | B38: 金 | C38: PhoenixJP | E38: - | I38: VainqueurJP | K38: - | L38: - | M38: RaиkSS | O38: - | P38: 宴会 | U38: TheEnd | W38: 統一 | X38: 宴会 | Y38: 黒の太陽 | AA38: - | AB38: - | AC38: Kopitiam | AE38: - | AF38: - | AG38: RëBîrth | AI38: - | AJ38: - | AK38: 一DEFlANCE | AM38: - | AN38: -
A39: =A38+1 -> 45920 | B39: 土
A40: =A39+1 -> 45921 | B40: 日 | C40: ・殺戮・ | E40: 宴会 | I40: MystSA | K40: - | L40: 宴会 | M40: ZirconiA | O40: - | P40: - | U40: βυsнỉȉdo家族 | W40: 統一 | X40: - | Y40: シェイド | AA40: 統一 | AB40: - | AC40: Anino | AE40: - | AF40: 宴会 | AG40: 義勇 | AI40: - | AJ40: - | AM40: - | AN40: -
...

Sheet 税収
B2: 45886 | C2: 22時 | D2: 城塞 | E2: 枠 | F2: 人数 | G2: 統一 | H2: 宴会 | I2: 税 | J2: 保有 | K2: =B2+1 -> 45887 | L2: 22時 | M2: 種別 | N2: 枠 | O2: 人数 | P2: 統一 | Q2: 宴会 | R2: 税 | S2: 保有 | T2: =K2+3 -> 45890 | U2: 22時 | V2: 種別 | W2: 枠 | X2: 人数 | Y2: 統一 | Z2: 宴会 | AA2: 税 | AB2: 保有 | AC2: =T2+1 -> 45891 | AD2: 22時 | AE2: 種別 | AF2: 枠 | AG2: 人数 | AH2: 統一 | AI2: 宴会 | AJ2: 税 | AK2: 保有
B3: デルニール農場 | C3: {=_xludf.XLOOKUP(B3,計算用!$R$2:$R$36,計算用!$S$2:$S$36)<>19} -> #NAME? | D3: {=_xludf.XLOOKUP(B3,計算用!$R:$R,計算用!$W:$W)} -> #NAME? | E3: {=_xludf.XLOOKUP(B3,計算用!$R:$R,計算用!$Y:$Y)} -> #NAME? | F3: {=_xludf.XLOOKUP(B3,計算用!$R:$R,計算用!$X:$X)} -> #NAME? | G3: - | H3: {=_xludf.XLOOKUP(B2,DB!$A:$A,DB!$F:$F)} -> #NAME? | I3: {=_xludf.XLOOKUP(B2,DB!$A:$A,DB!$G:$G)} -> #NAME? | J3: {=IF(_xludf.IFNA(I3=0,TRUE),_xludf.XLOOKUP(B2-7,DB!$A:$A,DB!$C:$C),計算用!$C$4)} -> #NAME? | K3: ルツム族駐屯地 | L3: {=_xludf.XLOOKUP(K3,計算用!$R$2:$R$36,計算用!$S$2:$S$36)<>19} -> #NAME? | M3: {=_xludf.XLOOKUP(K3,計算用!$R:$R,計算用!$W:$W)} -> #NAME? | N3: {=_xludf.XLOOKUP(K3,計算用!$R:$R,計算用!$Y:$Y)} -> #NAME? | O3: {=_xludf.XLOOKUP(K3,計算用!$R:$R,計算用!$X:$X)} -> #NAME? | P3: - | Q3: {=_xludf.XLOOKUP(K2,DB!$A:$A,DB!$F:$F)} -> #NAME? | R3: {=_xludf.XLOOKUP(K2,DB!$A:$A,DB!$G:$G)} -> #NAME? | S3: {=IF(_xludf.IFNA(R3=0,TRUE),_xludf.XLOOKUP(K2-7,DB!$A:$A,DB!$C:$C),計算用!$C$4)} -> #NAME? | T3: 北部大農場 | U3: {=_xludf.XLOOKUP(T3,計算用!$R$2:$R$36,計算用!$S$2:$S$36)<>19} -> #NAME? | V3: {=_xludf.XLOOKUP(T3,計算用!$R:$R,計算用!$W:$W)} -> #NAME? | W3: {=_xludf.XLOOKUP(T3,計算用!$R:$R,計算用!$Y:$Y)} -> #NAME? | X3: {=_xludf.XLOOKUP(T3,計算用!$R:$R,計算用!$X:$X)} -> #NAME? | Y3: - | Z3: {=_xludf.XLOOKUP(T2,DB!$A:$A,DB!$F:$F)} -> #NAME? | AA3: {=_xludf.XLOOKUP(T2,DB!$A:$A,DB!$G:$G)} -> #NAME? | AB3: {=IF(_xludf.IFNA(AA3=0,TRUE),_xludf.XLOOKUP(T2-7,DB!$A:$A,DB!$C:$C),計算用!$C$4)} -> #NAME? | AC3: アグリス祭壇 | AD3: {=_xludf.XLOOKUP(AC3,計算用!$R$2:$R$36,計算用!$S$2:$S$36)<>19} -> #NAME? | AE3: {=_xludf.XLOOKUP(AC3,計算用!$R:$R,計算用!$W:$W)} -> #NAME? | AF3: {=_xludf.XLOOKUP(AC3,計算用!$R:$R,計算用!$Y:$Y)} -> #NAME? | AG3: {=_xludf.XLOOKUP(AC3,計算用!$R:$R,計算用!$X:$X)} -> #NAME? | AH3: - | AI3: {=_xludf.XLOOKUP(AC2,DB!$A:$A,DB!$F:$F)} -> #NAME? | AJ3: {=_xludf.XLOOKUP(AC2,DB!$A:$A,DB!$G:$G)} -> #NAME? | AK3: {=IF(_xludf.IFNA(AJ3=0,TRUE),_xludf.XLOOKUP(AC2-7,DB!$A:$A,DB!$C:$C),計算用!$C$4)} -> #NAME?
K4: アト農場 | L4: {=_xludf.XLOOKUP(K4,計算用!$R$2:$R$36,計算用!$S$2:$S$36)<>19} -> #NAME? | M4: {=_xludf.XLOOKUP(K4,計算用!$R:$R,計算用!$W:$W)} -> #NAME? | N4: {=_xludf.XLOOKUP(K4,計算用!$R:$R,計算用!$Y:$Y)} -> #NAME? | O4: {=_xludf.XLOOKUP(K4,計算用!$R:$R,計算用!$X:$X)} -> #NAME? | P4: - | Q4: {=_xludf.XLOOKUP(K2,DB!$A:$A,DB!$M:$M)} -> #NAME? | R4: {=_xludf.XLOOKUP(K2,DB!$A:$A,DB!$N:$N)} -> #NAME? | S4: {=IF(_xludf.IFNA(R4=0,TRUE),_xludf.XLOOKUP(K2-7,DB!$A:$A,DB!$J:$J),計算用!$C$4)} -> #NAME?
B5: 略奪の森 | C5: {=_xludf.XLOOKUP(B5,計算用!$R$2:$R$36,計算用!$S$2:$S$36)<>19} -> #NAME? | D5: {=_xludf.XLOOKUP(B5,計算用!$R:$R,計算用!$W:$W)} -> #NAME? | E5: {=_xludf.XLOOKUP(B5,計算用!$R:$R,計算用!$Y:$Y)} -> #NAME? | F5: {=_xludf.XLOOKUP(B5,計算用!$R:$R,計算用!$X:$X)} -> #NAME? | G5: {=_xludf.XLOOKUP(B2,DB!$A:$A,DB!$T:$T)} -> #NAME? | H5: {=_xludf.XLOOKUP(B2,DB!$A:$A,DB!$U:$U)} -> #NAME? | I5: {=_xludf.XLOOKUP(B2,DB!$A:$A,DB!$V:$V)} -> #NAME? | J5: {=IF(_xludf.IFNA(I5=0,TRUE),_xludf.XLOOKUP(B2-7,DB!$A:$A,DB!$Q:$Q),計算用!$C$4)} -> #NAME? | K5: ベリア農場地帯 | L5: {=_xludf.XLOOKUP(K5,計算用!$R$2:$R$36,計算用!$S$2:$S$36)<>19} -> #NAME? | M5: {=_xludf.XLOOKUP(K5,計算用!$R:$R,計算用!$W:$W)} -> #NAME? | N5: {=_xludf.XLOOKUP(K5,計算用!$R:$R,計算用!$Y:$Y)} -> #NAME? | O5: {=_xludf.XLOOKUP(K5,計算用!$R:$R,計算用!$X:$X)} -> #NAME? | P5: {=_xludf.XLOOKUP(K2,DB!$A:$A,DB!$T:$T)} -> #NAME? | Q5: {=_xludf.XLOOKUP(K2,DB!$A:$A,DB!$U:$U)} -> #NAME? | R5: {=_xludf.XLOOKUP(K2,DB!$A:$A,DB!$V:$V)} -> #NAME? | S5: {=IF(_xludf.IFNA(R5=0,TRUE),_xludf.XLOOKUP(K2-7,DB!$A:$A,DB!$Q:$Q),計算用!$C$4)} -> #NAME? | T5: トロル防御基地 | U5: {=_xludf.XLOOKUP(T5,計算用!$R$2:$R$36,計算用!$S$2:$S$36)<>19} -> #NAME? | V5: {=_xludf.XLOOKUP(T5,計算用!$R:$R,計算用!$W:$W)} -> #NAME? | W5: {=_xludf.XLOOKUP(T5,計算用!$R:$R,計算用!$Y:$Y)} -> #NAME? | X5: {=_xludf.XLOOKUP(T5,計算用!$R:$R,計算用!$X:$X)} -> #NAME? | Y5: {=_xludf.XLOOKUP(T2,DB!$A:$A,DB!$T:$T)} -> #NAME? | Z5: {=_xludf.XLOOKUP(T2,DB!$A:$A,DB!$U:$U)} -> #NAME? | AA5: {=_xludf.XLOOKUP(T2,DB!$A:$A,DB!$V:$V)} -> #NAME? | AB5: {=IF(_xludf.IFNA(AA5=0,TRUE),_xludf.XLOOKUP(T2-7,DB!$A:$A,DB!$Q:$Q),計算用!$C$4)} -> #NAME? | AC5: ナーガ抽出場 | AD5: {=_xludf.XLOOKUP(AC5,計算用!$R$2:$R$36,計算用!$S$2:$S$36)<>19} -> #NAME? | AE5: {=_xludf.XLOOKUP(AC5,計算用!$R:$R,計算用!$W:$W)} -> #NAME? | AF5: {=_xludf.XLOOKUP(AC5,計算用!$R:$R,計算用!$Y:$Y)} -> #NAME? | AG5: {=_xludf.XLOOKUP(AC5,計算用!$R:$R,計算用!$X:$X)} -> #NAME? | AH5: {=_xludf.XLOOKUP(AC2,DB!$A:$A,DB!$T:$T)} -> #NAME? | AI5: {=_xludf.XLOOKUP(AC2,DB!$A:$A,DB!$U:$U)} -> #NAME? | AJ5: {=_xludf.XLOOKUP(AC2,DB!$A:$A,DB!$V:$V)} -> #NAME? | AK5: {=IF(_xludf.IFNA(AJ5=0,TRUE),_xludf.XLOOKUP(AC2-7,DB!$A:$A,DB!$Q:$Q),計算用!$C$4)} -> #NAME?
B6: 忘却の地 | C6: {=_xludf.XLOOKUP(B6,計算用!$R$2:$R$36,計算用!$S$2:$S$36)<>19} -> #NAME? | D6: {=_xludf.XLOOKUP(B6,計算用!$R:$R,計算用!$W:$W)} -> #NAME? | E6: {=_xludf.XLOOKUP(B6,計算用!$R:$R,計算用!$Y:$Y)} -> #NAME? | F6: {=_xludf.XLOOKUP(B6,計算用!$R:$R,計算用!$X:$X)} -> #NAME? | G6: {=_xludf.XLOOKUP(B2,DB!$A:$A,DB!$AB:$AB)} -> #NAME? | H6: {=_xludf.XLOOKUP(B2,DB!$A:$A,DB!$AC:$AC)} -> #NAME? | I6: {=_xludf.XLOOKUP(B2,DB!$A:$A,DB!$AD:$AD)} -> #NAME? | J6: {=IF(_xludf.IFNA(I6=0,TRUE),_xludf.XLOOKUP(B2-7,DB!$A:$A,DB!$Y:$Y),計算用!$C$4)} -> #NAME? | K6: ギュントの丘 | L6: {=_xludf.XLOOKUP(K6,計算用!$R$2:$R$36,計算用!$S$2:$S$36)<>19} -> #NAME? | M6: {=_xludf.XLOOKUP(K6,計算用!$R:$R,計算用!$W:$W)} -> #NAME? | N6: {=_xludf.XLOOKUP(K6,計算用!$R:$R,計算用!$Y:$Y)} -> #NAME? | O6: {=_xludf.XLOOKUP(K6,計算用!$R:$R,計算用!$X:$X)} -> #NAME? | P6: {=_xludf.XLOOKUP(K2,DB!$A:$A,DB!$AB:$AB)} -> #NAME? | Q6: {=_xludf.XLOOKUP(K2,DB!$A:$A,DB!$AC:$AC)} -> #NAME? | R6: {=_xludf.XLOOKUP(K2,DB!$A:$A,DB!$AD:$AD)} -> #NAME? | S6: {=IF(_xludf.IFNA(R6=0,TRUE),_xludf.XLOOKUP(K2-7,DB!$A:$A,DB!$Y:$Y),計算用!$C$4)} -> #NAME? | T6: 隠された修道院 | U6: {=_xludf.XLOOKUP(T6,計算用!$R$2:$R$36,計算用!$S$2:$S$36)<>19} -> #NAME? | V6: {=_xludf.XLOOKUP(T6,計算用!$R:$R,計算用!$W:$W)} -> #NAME? | W6: {=_xludf.XLOOKUP(T6,計算用!$R:$R,計算用!$Y:$Y)} -> #NAME? | X6: {=_xludf.XLOOKUP(T6,計算用!$R:$R,計算用!$X:$X)} -> #NAME? | Y6: {=_xludf.XLOOKUP(T2,DB!$A:$A,DB!$AB:$AB)} -> #NAME? | Z6: {=_xludf.XLOOKUP(T2,DB!$A:$A,DB!$AC:$AC)} -> #NAME? | AA6: {=_xludf.XLOOKUP(T2,DB!$A:$A,DB!$AD:$AD)} -> #NAME? | AB6: {=IF(_xludf.IFNA(AA6=0,TRUE),_xludf.XLOOKUP(T2-7,DB!$A:$A,DB!$Y:$Y),計算用!$C$4)} -> #NAME? | AC6: オークキャンプ | AD6: {=_xludf.XLOOKUP(AC6,計算用!$R$2:$R$36,計算用!$S$2:$S$36)<>19} -> #NAME? | AE6: {=_xludf.XLOOKUP(AC6,計算用!$R:$R,計算用!$W:$W)} -> #NAME? | AF6: {=_xludf.XLOOKUP(AC6,計算用!$R:$R,計算用!$Y:$Y)} -> #NAME? | AG6: {=_xludf.XLOOKUP(AC6,計算用!$R:$R,計算用!$X:$X)} -> #NAME? | AH6: {=_xludf.XLOOKUP(AC2,DB!$A:$A,DB!$AB:$AB)} -> #NAME? | AI6: {=_xludf.XLOOKUP(AC2,DB!$A:$A,DB!$AC:$AC)} -> #NAME? | AJ6: {=_xludf.XLOOKUP(AC2,DB!$A:$A,DB!$AD:$AD)} -> #NAME? | AK6: {=IF(_xludf.IFNA(AJ6=0,TRUE),_xludf.XLOOKUP(AC2-7,DB!$A:$A,DB!$Y:$Y),計算用!$C$4)} -> #NAME?
K7: 高原地帯 | L7: {=_xludf.XLOOKUP(K7,計算用!$R$2:$R$36,計算用!$S$2:$S$36)<>19} -> #NAME? | M7: {=_xludf.XLOOKUP(K7,計算用!$R:$R,計算用!$W:$W)} -> #NAME? | N7: {=_xludf.XLOOKUP(K7,計算用!$R:$R,計算用!$Y:$Y)} -> #NAME? | O7: {=_xludf.XLOOKUP(K7,計算用!$R:$R,計算用!$X:$X)} -> #NAME? | P7: {=_xludf.XLOOKUP(K2,DB!$A:$A,DB!$AJ:$AJ)} -> #NAME? | Q7: {=_xludf.XLOOKUP(K2,DB!$A:$A,DB!$AK:$AK)} -> #NAME? | R7: {=_xludf.XLOOKUP(K2,DB!$A:$A,DB!$AL:$AL)} -> #NAME? | S7: {=IF(_xludf.IFNA(R7=0,TRUE),_xludf.XLOOKUP(K2-7,DB!$A:$A,DB!$AG:$AG),計算用!$C$4)} -> #NAME? | T7: マルニの第2実験場 | U7: {=_xludf.XLOOKUP(T7,計算用!$R$2:$R$36,計算用!$S$2:$S$36)<>19} -> #NAME? | V7: {=_xludf.XLOOKUP(T7,計算用!$R:$R,計算用!$W:$W)} -> #NAME? | W7: {=_xludf.XLOOKUP(T7,計算用!$R:$R,計算用!$Y:$Y)} -> #NAME? | X7: {=_xludf.XLOOKUP(T7,計算用!$R:$R,計算用!$X:$X)} -> #NAME? | Y7: {=_xludf.XLOOKUP(T2,DB!$A:$A,DB!$AJ:$AJ)} -> #NAME? | Z7: {=_xludf.XLOOKUP(T2,DB!$A:$A,DB!$AK:$AK)} -> #NAME? | AA7: {=_xludf.XLOOKUP(T2,DB!$A:$A,DB!$AL:$AL)} -> #NAME? | AB7: {=IF(_xludf.IFNA(AA7=0,TRUE),_xludf.XLOOKUP(T2-7,DB!$A:$A,DB!$AG:$AG),計算用!$C$4)} -> #NAME?
B8: ナーガ沼地 | C8: {=_xludf.XLOOKUP(B8,計算用!$R$2:$R$36,計算用!$S$2:$S$36)<>19} -> #NAME? | D8: {=_xludf.XLOOKUP(B8,計算用!$R:$R,計算用!$W:$W)} -> #NAME? | E8: {=_xludf.XLOOKUP(B8,計算用!$R:$R,計算用!$Y:$Y)} -> #NAME? | F8: {=_xludf.XLOOKUP(B8,計算用!$R:$R,計算用!$X:$X)} -> #NAME? | G8: {=_xludf.XLOOKUP(B2,DB!$A:$A,DB!$AR:$AR)} -> #NAME? | H8: {=_xludf.XLOOKUP(B2,DB!$A:$A,DB!$AS:$AS)} -> #NAME? | I8: {=_xludf.XLOOKUP(B2,DB!$A:$A,DB!$AT:$AT)} -> #NAME? | J8: {=IF(_xludf.IFNA(I8=0,TRUE),_xludf.XLOOKUP(B2-7,DB!$A:$A,DB!$AO:$AO),計算用!$C$4)} -> #NAME? | K8: 隠遁の森 | L8: {=_xludf.XLOOKUP(K8,計算用!$R$2:$R$36,計算用!$S$2:$S$36)<>19} -> #NAME? | M8: {=_xludf.XLOOKUP(K8,計算用!$R:$R,計算用!$W:$W)} -> #NAME? | N8: {=_xludf.XLOOKUP(K8,計算用!$R:$R,計算用!$Y:$Y)} -> #NAME? | O8: {=_xludf.XLOOKUP(K8,計算用!$R:$R,計算用!$X:$X)} -> #NAME? | P8: {=_xludf.XLOOKUP(K2,DB!$A:$A,DB!$AR:$AR)} -> #NAME? | Q8: {=_xludf.XLOOKUP(K2,DB!$A:$A,DB!$AS:$AS)} -> #NAME? | R8: {=_xludf.XLOOKUP(K2,DB!$A:$A,DB!$AT:$AT)} -> #NAME? | S8: {=IF(_xludf.IFNA(R8=0,TRUE),_xludf.XLOOKUP(K2-7,DB!$A:$A,DB!$AO:$AO),計算用!$C$4)} -> #NAME? | T8: アグリス平原 | U8: {=_xludf.XLOOKUP(T8,計算用!$R$2:$R$36,計算用!$S$2:$S$36)<>19} -> #NAME? | V8: {=_xludf.XLOOKUP(T8,計算用!$R:$R,計算用!$W:$W)} -> #NAME? | W8: {=_xludf.XLOOKUP(T8,計算用!$R:$R,計算用!$Y:$Y)} -> #NAME? | X8: {=_xludf.XLOOKUP(T8,計算用!$R:$R,計算用!$X:$X)} -> #NAME? | Y8: {=_xludf.XLOOKUP(T2,DB!$A:$A,DB!$AR:$AR)} -> #NAME? | Z8: {=_xludf.XLOOKUP(T2,DB!$A:$A,DB!$AS:$AS)} -> #NAME? | AA8: {=_xludf.XLOOKUP(T2,DB!$A:$A,DB!$AT:$AT)} -> #NAME? | AB8: {=IF(_xludf.IFNA(AA8=0,TRUE),_xludf.XLOOKUP(T2-7,DB!$A:$A,DB!$AO:$AO),計算用!$C$4)} -> #NAME? | AC8: 北部採石場 | AD8: {=_xludf.XLOOKUP(AC8,計算用!$R$2:$R$36,計算用!$S$2:$S$36)<>19} -> #NAME? | AE8: {=_xludf.XLOOKUP(AC8,計算用!$R:$R,計算用!$W:$W)} -> #NAME? | AF8: {=_xludf.XLOOKUP(AC8,計算用!$R:$R,計算用!$Y:$Y)} -> #NAME? | AG8: {=_xludf.XLOOKUP(AC8,計算用!$R:$R,計算用!$X:$X)} -> #NAME? | AH8: {=_xludf.XLOOKUP(AC2,DB!$A:$A,DB!$AR:$AR)} -> #NAME? | AI8: {=_xludf.XLOOKUP(AC2,DB!$A:$A,DB!$AS:$AS)} -> #NAME? | AJ8: {=_xludf.XLOOKUP(AC2,DB!$A:$A,DB!$AT:$AT)} -> #NAME? | AK8: {=IF(_xludf.IFNA(AJ8=0,TRUE),_xludf.XLOOKUP(AC2-7,DB!$A:$A,DB!$AO:$AO),計算用!$C$4)} -> #NAME?
B9: 旧ダンデリオン | C9: {=_xludf.XLOOKUP(B9,計算用!$R$2:$R$36,計算用!$S$2:$S$36)<>19} -> #NAME? | D9: {=_xludf.XLOOKUP(B9,計算用!$R:$R,計算用!$W:$W)} -> #NAME? | E9: {=_xludf.XLOOKUP(B9,計算用!$R:$R,計算用!$Y:$Y)} -> #NAME? | F9: {=_xludf.XLOOKUP(B9,計算用!$R:$R,計算用!$X:$X)} -> #NAME? | G9: {=_xludf.XLOOKUP(B2,DB!$A:$A,DB!$AZ:$AZ)} -> #NAME? | H9: {=_xludf.XLOOKUP(B2,DB!$A:$A,DB!$BA:$BA)} -> #NAME? | I9: {=_xludf.XLOOKUP(B2,DB!$A:$A,DB!$BB:$BB)} -> #NAME? | J9: {=IF(_xludf.IFNA(I9=0,TRUE),_xludf.XLOOKUP(B2-7,DB!$A:$A,DB!$AW:$AW),計算用!$C$4)} -> #NAME? | K9: エワズの丘 | L9: {=_xludf.XLOOKUP(K9,計算用!$R$2:$R$36,計算用!$S$2:$S$36)<>19} -> #NAME? | M9: {=_xludf.XLOOKUP(K9,計算用!$R:$R,計算用!$W:$W)} -> #NAME? | N9: {=_xludf.XLOOKUP(K9,計算用!$R:$R,計算用!$Y:$Y)} -> #NAME? | O9: {=_xludf.XLOOKUP(K9,計算用!$R:$R,計算用!$X:$X)} -> #NAME? | P9: {=_xludf.XLOOKUP(K2,DB!$A:$A,DB!$AZ:$AZ)} -> #NAME? | Q9: {=_xludf.XLOOKUP(K2,DB!$A:$A,DB!$BA:$BA)} -> #NAME? | R9: {=_xludf.XLOOKUP(K2,DB!$A:$A,DB!$BB:$BB)} -> #NAME? | S9: {=IF(_xludf.IFNA(R9=0,TRUE),_xludf.XLOOKUP(K2-7,DB!$A:$A,DB!$AW:$AW),計算用!$C$4)} -> #NAME? | T9: リンチ農場廃墟 | U9: {=_xludf.XLOOKUP(T9,計算用!$R$2:$R$36,計算用!$S$2:$S$36)<>19} -> #NAME? | V9: {=_xludf.XLOOKUP(T9,計算用!$R:$R,計算用!$W:$W)} -> #NAME? | W9: {=_xludf.XLOOKUP(T9,計算用!$R:$R,計算用!$Y:$Y)} -> #NAME? | X9: {=_xludf.XLOOKUP(T9,計算用!$R:$R,計算用!$X:$X)} -> #NAME? | Y9: {=_xludf.XLOOKUP(T2,DB!$A:$A,DB!$AZ:$AZ)} -> #NAME? | Z9: {=_xludf.XLOOKUP(T2,DB!$A:$A,DB!$BA:$BA)} -> #NAME? | AA9: {=_xludf.XLOOKUP(T2,DB!$A:$A,DB!$BB:$BB)} -> #NAME? | AB9: {=IF(_xludf.IFNA(AA9=0,TRUE),_xludf.XLOOKUP(T2-7,DB!$A:$A,DB!$AW:$AW),計算用!$C$4)} -> #NAME? | AC9: ハーピーの絶壁 | AD9: {=_xludf.XLOOKUP(AC9,計算用!$R$2:$R$36,計算用!$S$2:$S$36)<>19} -> #NAME? | AE9: {=_xludf.XLOOKUP(AC9,計算用!$R:$R,計算用!$W:$W)} -> #NAME? | AF9: {=_xludf.XLOOKUP(AC9,計算用!$R:$R,計算用!$Y:$Y)} -> #NAME? | AG9: {=_xludf.XLOOKUP(AC9,計算用!$R:$R,計算用!$X:$X)} -> #NAME? | AH9: {=_xludf.XLOOKUP(AC2,DB!$A:$A,DB!$AZ:$AZ)} -> #NAME? | AI9: {=_xludf.XLOOKUP(AC2,DB!$A:$A,DB!$BA:$BA)} -> #NAME? | AJ9: {=_xludf.XLOOKUP(AC2,DB!$A:$A,DB!$BB:$BB)} -> #NAME? | AK9: {=IF(_xludf.IFNA(AJ9=0,TRUE),_xludf.XLOOKUP(AC2-7,DB!$A:$A,DB!$AW:$AW),計算用!$C$4)} -> #NAME?
B10: 捨てられた地 | C10: {=_xludf.XLOOKUP(B10,計算用!$R$2:$R$36,計算用!$S$2:$S$36)<>19} -> #NAME? | D10: {=_xludf.XLOOKUP(B10,計算用!$R:$R,計算用!$W:$W)} -> #NAME? | E10: {=_xludf.XLOOKUP(B10,計算用!$R:$R,計算用!$Y:$Y)} -> #NAME? | F10: {=_xludf.XLOOKUP(B10,計算用!$R:$R,計算用!$X:$X)} -> #NAME? | G10: {=_xludf.XLOOKUP(B2,DB!$A:$A,DB!$BH:$BH)} -> #NAME? | H10: {=_xludf.XLOOKUP(B2,DB!$A:$A,DB!$BI:$BI)} -> #NAME? | I10: {=_xludf.XLOOKUP(B2,DB!$A:$A,DB!$BJ:$BJ)} -> #NAME? | J10: {=IF(_xludf.IFNA(I10=0,TRUE),_xludf.XLOOKUP(B2-7,DB!$A:$A,DB!$BE:$BE),計算用!$C$4)} -> #NAME? | K10: 廃城跡入り口 | L10: {=_xludf.XLOOKUP(K10,計算用!$R$2:$R$36,計算用!$S$2:$S$36)<>19} -> #NAME? | M10: {=_xludf.XLOOKUP(K10,計算用!$R:$R,計算用!$W:$W)} -> #NAME? | N10: {=_xludf.XLOOKUP(K10,計算用!$R:$R,計算用!$Y:$Y)} -> #NAME? | O10: {=_xludf.XLOOKUP(K10,計算用!$R:$R,計算用!$X:$X)} -> #NAME? | P10: {=_xludf.XLOOKUP(K2,DB!$A:$A,DB!$BH:$BH)} -> #NAME? | Q10: {=_xludf.XLOOKUP(K2,DB!$A:$A,DB!$BI:$BI)} -> #NAME? | R10: {=_xludf.XLOOKUP(K2,DB!$A:$A,DB!$BJ:$BJ)} -> #NAME? | S10: {=IF(_xludf.IFNA(R10=0,TRUE),_xludf.XLOOKUP(K2-7,DB!$A:$A,DB!$BE:$BE),計算用!$C$4)} -> #NAME? | T10: ブレディー砦 | U10: {=_xludf.XLOOKUP(T10,計算用!$R$2:$R$36,計算用!$S$2:$S$36)<>19} -> #NAME? | V10: {=_xludf.XLOOKUP(T10,計算用!$R:$R,計算用!$W:$W)} -> #NAME? | W10: {=_xludf.XLOOKUP(T10,計算用!$R:$R,計算用!$Y:$Y)} -> #NAME? | X10: {=_xludf.XLOOKUP(T10,計算用!$R:$R,計算用!$X:$X)} -> #NAME? | Y10: {=_xludf.XLOOKUP(T2,DB!$A:$A,DB!$BH:$BH)} -> #NAME? | Z10: {=_xludf.XLOOKUP(T2,DB!$A:$A,DB!$BI:$BI)} -> #NAME? | AA10: {=_xludf.XLOOKUP(T2,DB!$A:$A,DB!$BJ:$BJ)} -> #NAME? | AB10: {=IF(_xludf.IFNA(AA10=0,TRUE),_xludf.XLOOKUP(T2-7,DB!$A:$A,DB!$BE:$BE),計算用!$C$4)} -> #NAME? | AC10: ブリの森 | AD10: {=_xludf.XLOOKUP(AC10,計算用!$R$2:$R$36,計算用!$S$2:$S$36)<>19} -> #NAME? | AE10: {=_xludf.XLOOKUP(AC10,計算用!$R:$R,計算用!$W:$W)} -> #NAME? | AF10: {=_xludf.XLOOKUP(AC10,計算用!$R:$R,計算用!$Y:$Y)} -> #NAME? | AG10: {=_xludf.XLOOKUP(AC10,計算用!$R:$R,計算用!$X:$X)} -> #NAME? | AH10: {=_xludf.XLOOKUP(AC2,DB!$A:$A,DB!$BH:$BH)} -> #NAME? | AI10: {=_xludf.XLOOKUP(AC2,DB!$A:$A,DB!$BI:$BI)} -> #NAME? | AJ10: {=_xludf.XLOOKUP(AC2,DB!$A:$A,DB!$BJ:$BJ)} -> #NAME? | AK10: {=IF(_xludf.IFNA(AJ10=0,TRUE),_xludf.XLOOKUP(AC2-7,DB!$A:$A,DB!$BE:$BE),計算用!$C$4)} -> #NAME?
B11: ベア川下流 | C11: {=_xludf.XLOOKUP(B11,計算用!$R$2:$R$36,計算用!$S$2:$S$36)<>19} -> #NAME? | D11: {=_xludf.XLOOKUP(B11,計算用!$R:$R,計算用!$W:$W)} -> #NAME? | E11: {=_xludf.XLOOKUP(B11,計算用!$R:$R,計算用!$Y:$Y)} -> #NAME? | F11: {=_xludf.XLOOKUP(B11,計算用!$R:$R,計算用!$X:$X)} -> #NAME? | G11: {=_xludf.XLOOKUP(B2,DB!$A:$A,DB!$BP:$BP)} -> #NAME? | H11: {=_xludf.XLOOKUP(B2,DB!$A:$A,DB!$BQ:$BQ)} -> #NAME? | I11: {=_xludf.XLOOKUP(B2,DB!$A:$A,DB!$BR:$BR)} -> #NAME? | J11: {=IF(_xludf.IFNA(I11=0,TRUE),_xludf.XLOOKUP(B2-7,DB!$A:$A,DB!$BM:$BM),計算用!$C$4)} -> #NAME? | K11: カイア渡し場 | L11: {=_xludf.XLOOKUP(K11,計算用!$R$2:$R$36,計算用!$S$2:$S$36)<>19} -> #NAME? | M11: {=_xludf.XLOOKUP(K11,計算用!$R:$R,計算用!$W:$W)} -> #NAME? | N11: {=_xludf.XLOOKUP(K11,計算用!$R:$R,計算用!$Y:$Y)} -> #NAME? | O11: {=_xludf.XLOOKUP(K11,計算用!$R:$R,計算用!$X:$X)} -> #NAME? | P11: {=_xludf.XLOOKUP(K2,DB!$A:$A,DB!$BP:$BP)} -> #NAME? | Q11: {=_xludf.XLOOKUP(K2,DB!$A:$A,DB!$BQ:$BQ)} -> #NAME? | R11: {=_xludf.XLOOKUP(K2,DB!$A:$A,DB!$BR:$BR)} -> #NAME? | S11: {=IF(_xludf.IFNA(R11=0,TRUE),_xludf.XLOOKUP(K2-7,DB!$A:$A,DB!$BM:$BM),計算用!$C$4)} -> #NAME? | T11: エントの森 | U11: {=_xludf.XLOOKUP(T11,計算用!$R$2:$R$36,計算用!$S$2:$S$36)<>19} -> #NAME? | V11: {=_xludf.XLOOKUP(T11,計算用!$R:$R,計算用!$W:$W)} -> #NAME? | W11: {=_xludf.XLOOKUP(T11,計算用!$R:$R,計算用!$Y:$Y)} -> #NAME? | X11: {=_xludf.XLOOKUP(T11,計算用!$R:$R,計算用!$X:$X)} -> #NAME? | Y11: {=_xludf.XLOOKUP(T2,DB!$A:$A,DB!$BP:$BP)} -> #NAME? | Z11: {=_xludf.XLOOKUP(T2,DB!$A:$A,DB!$BQ:$BQ)} -> #NAME? | AA11: {=_xludf.XLOOKUP(T2,DB!$A:$A,DB!$BR:$BR)} -> #NAME? | AB11: {=IF(_xludf.IFNA(AA11=0,TRUE),_xludf.XLOOKUP(T2-7,DB!$A:$A,DB!$BM:$BM),計算用!$C$4)} -> #NAME? | AC11: マンシャの森の奥 | AD11: {=_xludf.XLOOKUP(AC11,計算用!$R$2:$R$36,計算用!$S$2:$S$36)<>19} -> #NAME? | AE11: {=_xludf.XLOOKUP(AC11,計算用!$R:$R,計算用!$W:$W)} -> #NAME? | AF11: {=_xludf.XLOOKUP(AC11,計算用!$R:$R,計算用!$Y:$Y)} -> #NAME? | AG11: {=_xludf.XLOOKUP(AC11,計算用!$R:$R,計算用!$X:$X)} -> #NAME? | AH11: {=_xludf.XLOOKUP(AC2,DB!$A:$A,DB!$BP:$BP)} -> #NAME? | AI11: {=_xludf.XLOOKUP(AC2,DB!$A:$A,DB!$BQ:$BQ)} -> #NAME? | AJ11: {=_xludf.XLOOKUP(AC2,DB!$A:$A,DB!$BR:$BR)} -> #NAME? | AK11: {=IF(_xludf.IFNA(AJ11=0,TRUE),_xludf.XLOOKUP(AC2-7,DB!$A:$A,DB!$BM:$BM),計算用!$C$4)} -> #NAME?
B12: アルティノ入り口 | C12: {=_xludf.XLOOKUP(B12,計算用!$R$2:$R$36,計算用!$S$2:$S$36)<>19} -> #NAME? | D12: {=_xludf.XLOOKUP(B12,計算用!$R:$R,計算用!$W:$W)} -> #NAME? | E12: {=_xludf.XLOOKUP(B12,計算用!$R:$R,計算用!$Y:$Y)} -> #NAME? | F12: {=_xludf.XLOOKUP(B12,計算用!$R:$R,計算用!$X:$X)} -> #NAME? | G12: {=_xludf.XLOOKUP(B2,DB!$A:$A,DB!$BX:$BX)} -> #NAME? | H12: {=_xludf.XLOOKUP(B2,DB!$A:$A,DB!$BY:$BY)} -> #NAME? | I12: {=_xludf.XLOOKUP(B2,DB!$A:$A,DB!$BZ:$BZ)} -> #NAME? | J12: {=IF(_xludf.IFNA(I12=0,TRUE),_xludf.XLOOKUP(B2-7,DB!$A:$A,DB!$BU:$BU),計算用!$C$4)} -> #NAME? | K12: カズラ農場 | L12: {=_xludf.XLOOKUP(K12,計算用!$R$2:$R$36,計算用!$S$2:$S$36)<>19} -> #NAME? | M12: {=_xludf.XLOOKUP(K12,計算用!$R:$R,計算用!$W:$W)} -> #NAME? | N12: {=_xludf.XLOOKUP(K12,計算用!$R:$R,計算用!$Y:$Y)} -> #NAME? | O12: {=_xludf.XLOOKUP(K12,計算用!$R:$R,計算用!$X:$X)} -> #NAME? | P12: {=_xludf.XLOOKUP(K2,DB!$A:$A,DB!$BX:$BX)} -> #NAME? | Q12: {=_xludf.XLOOKUP(K2,DB!$A:$A,DB!$BY:$BY)} -> #NAME? | R12: {=_xludf.XLOOKUP(K2,DB!$A:$A,DB!$BZ:$BZ)} -> #NAME? | S12: {=IF(_xludf.IFNA(R12=0,TRUE),_xludf.XLOOKUP(K2-7,DB!$A:$A,DB!$BU:$BU),計算用!$C$4)} -> #NAME? | T12: クリオ村 | U12: {=_xludf.XLOOKUP(T12,計算用!$R$2:$R$36,計算用!$S$2:$S$36)<>19} -> #NAME? | V12: {=_xludf.XLOOKUP(T12,計算用!$R:$R,計算用!$W:$W)} -> #NAME? | W12: {=_xludf.XLOOKUP(T12,計算用!$R:$R,計算用!$Y:$Y)} -> #NAME? | X12: {=_xludf.XLOOKUP(T12,計算用!$R:$R,計算用!$X:$X)} -> #NAME? | Y12: {=_xludf.XLOOKUP(T2,DB!$A:$A,DB!$BX:$BX)} -> #NAME? | Z12: {=_xludf.XLOOKUP(T2,DB!$A:$A,DB!$BY:$BY)} -> #NAME? | AA12: {=_xludf.XLOOKUP(T2,DB!$A:$A,DB!$BZ:$BZ)} -> #NAME? | AB12: {=IF(_xludf.IFNA(AA12=0,TRUE),_xludf.XLOOKUP(T2-7,DB!$A:$A,DB!$BU:$BU),計算用!$C$4)} -> #NAME? | AC12: 廃鉄鉱山採掘場 | AD12: {=_xludf.XLOOKUP(AC12,計算用!$R$2:$R$36,計算用!$S$2:$S$36)<>19} -> #NAME? | AE12: {=_xludf.XLOOKUP(AC12,計算用!$R:$R,計算用!$W:$W)} -> #NAME? | AF12: {=_xludf.XLOOKUP(AC12,計算用!$R:$R,計算用!$Y:$Y)} -> #NAME? | AG12: {=_xludf.XLOOKUP(AC12,計算用!$R:$R,計算用!$X:$X)} -> #NAME? | AH12: {=_xludf.XLOOKUP(AC2,DB!$A:$A,DB!$BX:$BX)} -> #NAME? | AI12: {=_xludf.XLOOKUP(AC2,DB!$A:$A,DB!$BY:$BY)} -> #NAME? | AJ12: {=_xludf.XLOOKUP(AC2,DB!$A:$A,DB!$BZ:$BZ)} -> #NAME? | AK12: {=IF(_xludf.IFNA(AJ12=0,TRUE),_xludf.XLOOKUP(AC2-7,DB!$A:$A,DB!$BU:$BU),計算用!$C$4)} -> #NAME?
B13: =B2+7 -> 45893 | C13: 22時 | D13: 城塞 | E13: 枠 | F13: 人数 | G13: 統一 | H13: 宴会 | I13: 税 | J13: 保有 | K13: =B13+1 -> 45894 | L13: 22時 | M13: 種別 | N13: 枠 | O13: 人数 | P13: 統一 | Q13: 宴会 | R13: 税 | S13: 保有 | T13: =K13+3 -> 45897 | U13: 22時 | V13: 種別 | W13: 枠 | X13: 人数 | Y13: 統一 | Z13: 宴会 | AA13: 税 | AB13: 保有 | AC13: =T13+1 -> 45898 | AD13: 22時 | AE13: 種別 | AF13: 枠 | AG13: 人数 | AH13: 統一 | AI13: 宴会 | AJ13: 税 | AK13: 保有
B14: デルニール農場 | C14: {=_xludf.XLOOKUP(B14,計算用!$R$2:$R$36,計算用!$S$2:$S$36)<>19} -> #NAME? | D14: {=_xludf.XLOOKUP(B14,計算用!$R:$R,計算用!$W:$W)} -> #NAME? | E14: {=_xludf.XLOOKUP(B14,計算用!$R:$R,計算用!$Y:$Y)} -> #NAME? | F14: {=_xludf.XLOOKUP(B14,計算用!$R:$R,計算用!$X:$X)} -> #NAME? | G14: - | H14: {=_xludf.XLOOKUP(B13,DB!$A:$A,DB!$F:$F)} -> #NAME? | I14: {=_xludf.XLOOKUP(B13,DB!$A:$A,DB!$G:$G)} -> #NAME? | J14: {=IF(_xludf.IFNA(I14=0,TRUE),_xludf.XLOOKUP(B13-7,DB!$A:$A,DB!$C:$C),計算用!$C$4)} -> #NAME? | K14: ルツム族駐屯地 | L14: {=_xludf.XLOOKUP(K14,計算用!$R$2:$R$36,計算用!$S$2:$S$36)<>19} -> #NAME? | M14: {=_xludf.XLOOKUP(K14,計算用!$R:$R,計算用!$W:$W)} -> #NAME? | N14: {=_xludf.XLOOKUP(K14,計算用!$R:$R,計算用!$Y:$Y)} -> #NAME? | O14: {=_xludf.XLOOKUP(K14,計算用!$R:$R,計算用!$X:$X)} -> #NAME? | P14: - | Q14: {=_xludf.XLOOKUP(K13,DB!$A:$A,DB!$F:$F)} -> #NAME? | R14: {=_xludf.XLOOKUP(K13,DB!$A:$A,DB!$G:$G)} -> #NAME? | S14: {=IF(_xludf.IFNA(R14=0,TRUE),_xludf.XLOOKUP(K13-7,DB!$A:$A,DB!$C:$C),計算用!$C$4)} -> #NAME? | T14: 北部大農場 | U14: {=_xludf.XLOOKUP(T14,計算用!$R$2:$R$36,計算用!$S$2:$S$36)<>19} -> #NAME? | V14: {=_xludf.XLOOKUP(T14,計算用!$R:$R,計算用!$W:$W)} -> #NAME? | W14: {=_xludf.XLOOKUP(T14,計算用!$R:$R,計算用!$Y:$Y)} -> #NAME? | X14: {=_xludf.XLOOKUP(T14,計算用!$R:$R,計算用!$X:$X)} -> #NAME? | Y14: - | Z14: {=_xludf.XLOOKUP(T13,DB!$A:$A,DB!$F:$F)} -> #NAME? | AA14: {=_xludf.XLOOKUP(T13,DB!$A:$A,DB!$G:$G)} -> #NAME? | AB14: {=IF(_xludf.IFNA(AA14=0,TRUE),_xludf.XLOOKUP(T13-7,DB!$A:$A,DB!$C:$C),計算用!$C$4)} -> #NAME? | AC14: アグリス祭壇 | AD14: {=_xludf.XLOOKUP(AC14,計算用!$R$2:$R$36,計算用!$S$2:$S$36)<>19} -> #NAME? | AE14: {=_xludf.XLOOKUP(AC14,計算用!$R:$R,計算用!$W:$W)} -> #NAME? | AF14: {=_xludf.XLOOKUP(AC14,計算用!$R:$R,計算用!$Y:$Y)} -> #NAME? | AG14: {=_xludf.XLOOKUP(AC14,計算用!$R:$R,計算用!$X:$X)} -> #NAME? | AH14: - | AI14: {=_xludf.XLOOKUP(AC13,DB!$A:$A,DB!$F:$F)} -> #NAME? | AJ14: {=_xludf.XLOOKUP(AC13,DB!$A:$A,DB!$G:$G)} -> #NAME? | AK14: {=IF(_xludf.IFNA(AJ14=0,TRUE),_xludf.XLOOKUP(AC13-7,DB!$A:$A,DB!$C:$C),計算用!$C$4)} -> #NAME?
J15: {=IF(_xludf.IFNA(I15=0,TRUE),_xludf.XLOOKUP(B13-7,DB!$A:$A,DB!$J:$J),計算用!$C$4)} -> #NAME? | K15: アト農場 | L15: {=_xludf.XLOOKUP(K15,計算用!$R$2:$R$36,計算用!$S$2:$S$36)<>19} -> #NAME? | M15: {=_xludf.XLOOKUP(K15,計算用!$R:$R,計算用!$W:$W)} -> #NAME? | N15: {=_xludf.XLOOKUP(K15,計算用!$R:$R,計算用!$Y:$Y)} -> #NAME? | O15: {=_xludf.XLOOKUP(K15,計算用!$R:$R,計算用!$X:$X)} -> #NAME? | P15: - | Q15: {=_xludf.XLOOKUP(K13,DB!$A:$A,DB!$M:$M)} -> #NAME? | R15: {=_xludf.XLOOKUP(K13,DB!$A:$A,DB!$N:$N)} -> #NAME? | S15: {=IF(_xludf.IFNA(R15=0,TRUE),_xludf.XLOOKUP(K13-7,DB!$A:$A,DB!$J:$J),計算用!$C$4)} -> #NAME?
B16: 略奪の森 | C16: {=_xludf.XLOOKUP(B16,計算用!$R$2:$R$36,計算用!$S$2:$S$36)<>19} -> #NAME? | D16: {=_xludf.XLOOKUP(B16,計算用!$R:$R,計算用!$W:$W)} -> #NAME? | E16: {=_xludf.XLOOKUP(B16,計算用!$R:$R,計算用!$Y:$Y)} -> #NAME? | F16: {=_xludf.XLOOKUP(B16,計算用!$R:$R,計算用!$X:$X)} -> #NAME? | G16: {=_xludf.XLOOKUP(B13,DB!$A:$A,DB!$T:$T)} -> #NAME? | H16: {=_xludf.XLOOKUP(B13,DB!$A:$A,DB!$U:$U)} -> #NAME? | I16: {=_xludf.XLOOKUP(B13,DB!$A:$A,DB!$V:$V)} -> #NAME? | J16: {=IF(_xludf.IFNA(I16=0,TRUE),_xludf.XLOOKUP(B13-7,DB!$A:$A,DB!$Q:$Q),計算用!$C$4)} -> #NAME? | K16: ベリア農場地帯 | L16: {=_xludf.XLOOKUP(K16,計算用!$R$2:$R$36,計算用!$S$2:$S$36)<>19} -> #NAME? | M16: {=_xludf.XLOOKUP(K16,計算用!$R:$R,計算用!$W:$W)} -> #NAME? | N16: {=_xludf.XLOOKUP(K16,計算用!$R:$R,計算用!$Y:$Y)} -> #NAME? | O16: {=_xludf.XLOOKUP(K16,計算用!$R:$R,計算用!$X:$X)} -> #NAME? | P16: {=_xludf.XLOOKUP(K13,DB!$A:$A,DB!$T:$T)} -> #NAME? | Q16: {=_xludf.XLOOKUP(K13,DB!$A:$A,DB!$U:$U)} -> #NAME? | R16: {=_xludf.XLOOKUP(K13,DB!$A:$A,DB!$V:$V)} -> #NAME? | S16: {=IF(_xludf.IFNA(R16=0,TRUE),_xludf.XLOOKUP(K13-7,DB!$A:$A,DB!$Q:$Q),計算用!$C$4)} -> #NAME? | T16: トロル防御基地 | U16: {=_xludf.XLOOKUP(T16,計算用!$R$2:$R$36,計算用!$S$2:$S$36)<>19} -> #NAME? | V16: {=_xludf.XLOOKUP(T16,計算用!$R:$R,計算用!$W:$W)} -> #NAME? | W16: {=_xludf.XLOOKUP(T16,計算用!$R:$R,計算用!$Y:$Y)} -> #NAME? | X16: {=_xludf.XLOOKUP(T16,計算用!$R:$R,計算用!$X:$X)} -> #NAME? | Y16: {=_xludf.XLOOKUP(T13,DB!$A:$A,DB!$T:$T)} -> #NAME? | Z16: {=_xludf.XLOOKUP(T13,DB!$A:$A,DB!$U:$U)} -> #NAME? | AA16: {=_xludf.XLOOKUP(T13,DB!$A:$A,DB!$V:$V)} -> #NAME? | AB16: {=IF(_xludf.IFNA(AA16=0,TRUE),_xludf.XLOOKUP(T13-7,DB!$A:$A,DB!$Q:$Q),計算用!$C$4)} -> #NAME? | AC16: ナーガ抽出場 | AD16: {=_xludf.XLOOKUP(AC16,計算用!$R$2:$R$36,計算用!$S$2:$S$36)<>19} -> #NAME? | AE16: {=_xludf.XLOOKUP(AC16,計算用!$R:$R,計算用!$W:$W)} -> #NAME? | AF16: {=_xludf.XLOOKUP(AC16,計算用!$R:$R,計算用!$Y:$Y)} -> #NAME? | AG16: {=_xludf.XLOOKUP(AC16,計算用!$R:$R,計算用!$X:$X)} -> #NAME? | AH16: {=_xludf.XLOOKUP(AC13,DB!$A:$A,DB!$T:$T)} -> #NAME? | AI16: {=_xludf.XLOOKUP(AC13,DB!$A:$A,DB!$U:$U)} -> #NAME? | AJ16: {=_xludf.XLOOKUP(AC13,DB!$A:$A,DB!$V:$V)} -> #NAME? | AK16: {=IF(_xludf.IFNA(AJ16=0,TRUE),_xludf.XLOOKUP(AC13-7,DB!$A:$A,DB!$Q:$Q),計算用!$C$4)} -> #NAME?
B17: 忘却の地 | C17: {=_xludf.XLOOKUP(B17,計算用!$R$2:$R$36,計算用!$S$2:$S$36)<>19} -> #NAME? | D17: {=_xludf.XLOOKUP(B17,計算用!$R:$R,計算用!$W:$W)} -> #NAME? | E17: {=_xludf.XLOOKUP(B17,計算用!$R:$R,計算用!$Y:$Y)} -> #NAME? | F17: {=_xludf.XLOOKUP(B17,計算用!$R:$R,計算用!$X:$X)} -> #NAME? | G17: {=_xludf.XLOOKUP(B13,DB!$A:$A,DB!$AB:$AB)} -> #NAME? | H17: {=_xludf.XLOOKUP(B13,DB!$A:$A,DB!$AC:$AC)} -> #NAME? | I17: {=_xludf.XLOOKUP(B13,DB!$A:$A,DB!$AD:$AD)} -> #NAME? | J17: {=IF(_xludf.IFNA(I17=0,TRUE),_xludf.XLOOKUP(B13-7,DB!$A:$A,DB!$Y:$Y),計算用!$C$4)} -> #NAME? | K17: ギュントの丘 | L17: {=_xludf.XLOOKUP(K17,計算用!$R$2:$R$36,計算用!$S$2:$S$36)<>19} -> #NAME? | M17: {=_xludf.XLOOKUP(K17,計算用!$R:$R,計算用!$W:$W)} -> #NAME? | N17: {=_xludf.XLOOKUP(K17,計算用!$R:$R,計算用!$Y:$Y)} -> #NAME? | O17: {=_xludf.XLOOKUP(K17,計算用!$R:$R,計算用!$X:$X)} -> #NAME? | P17: {=_xludf.XLOOKUP(K13,DB!$A:$A,DB!$AB:$AB)} -> #NAME? | Q17: {=_xludf.XLOOKUP(K13,DB!$A:$A,DB!$AC:$AC)} -> #NAME? | R17: {=_xludf.XLOOKUP(K13,DB!$A:$A,DB!$AD:$AD)} -> #NAME? | S17: {=IF(_xludf.IFNA(R17=0,TRUE),_xludf.XLOOKUP(K13-7,DB!$A:$A,DB!$Y:$Y),計算用!$C$4)} -> #NAME? | T17: 隠された修道院 | U17: {=_xludf.XLOOKUP(T17,計算用!$R$2:$R$36,計算用!$S$2:$S$36)<>19} -> #NAME? | V17: {=_xludf.XLOOKUP(T17,計算用!$R:$R,計算用!$W:$W)} -> #NAME? | W17: {=_xludf.XLOOKUP(T17,計算用!$R:$R,計算用!$Y:$Y)} -> #NAME? | X17: {=_xludf.XLOOKUP(T17,計算用!$R:$R,計算用!$X:$X)} -> #NAME? | Y17: {=_xludf.XLOOKUP(T13,DB!$A:$A,DB!$AB:$AB)} -> #NAME? | Z17: {=_xludf.XLOOKUP(T13,DB!$A:$A,DB!$AC:$AC)} -> #NAME? | AA17: {=_xludf.XLOOKUP(T13,DB!$A:$A,DB!$AD:$AD)} -> #NAME? | AB17: {=IF(_xludf.IFNA(AA17=0,TRUE),_xludf.XLOOKUP(T13-7,DB!$A:$A,DB!$Y:$Y),計算用!$C$4)} -> #NAME? | AC17: オークキャンプ | AD17: {=_xludf.XLOOKUP(AC17,計算用!$R$2:$R$36,計算用!$S$2:$S$36)<>19} -> #NAME? | AE17: {=_xludf.XLOOKUP(AC17,計算用!$R:$R,計算用!$W:$W)} -> #NAME? | AF17: {=_xludf.XLOOKUP(AC17,計算用!$R:$R,計算用!$Y:$Y)} -> #NAME? | AG17: {=_xludf.XLOOKUP(AC17,計算用!$R:$R,計算用!$X:$X)} -> #NAME? | AH17: {=_xludf.XLOOKUP(AC13,DB!$A:$A,DB!$AB:$AB)} -> #NAME? | AI17: {=_xludf.XLOOKUP(AC13,DB!$A:$A,DB!$AC:$AC)} -> #NAME? | AJ17: {=_xludf.XLOOKUP(AC13,DB!$A:$A,DB!$AD:$AD)} -> #NAME? | AK17: {=IF(_xludf.IFNA(AJ17=0,TRUE),_xludf.XLOOKUP(AC13-7,DB!$A:$A,DB!$Y:$Y),計算用!$C$4)} -> #NAME?
J18: {=IF(_xludf.IFNA(I18=0,TRUE),_xludf.XLOOKUP(B13-7,DB!$A:$A,DB!$AG:$AG),計算用!$C$4)} -> #NAME? | K18: 高原地帯 | L18: {=_xludf.XLOOKUP(K18,計算用!$R$2:$R$36,計算用!$S$2:$S$36)<>19} -> #NAME? | M18: {=_xludf.XLOOKUP(K18,計算用!$R:$R,計算用!$W:$W)} -> #NAME? | N18: {=_xludf.XLOOKUP(K18,計算用!$R:$R,計算用!$Y:$Y)} -> #NAME? | O18: {=_xludf.XLOOKUP(K18,計算用!$R:$R,計算用!$X:$X)} -> #NAME? | P18: {=_xludf.XLOOKUP(K13,DB!$A:$A,DB!$AJ:$AJ)} -> #NAME? | Q18: {=_xludf.XLOOKUP(K13,DB!$A:$A,DB!$AK:$AK)} -> #NAME? | R18: {=_xludf.XLOOKUP(K13,DB!$A:$A,DB!$AL:$AL)} -> #NAME? | S18: {=IF(_xludf.IFNA(R18=0,TRUE),_xludf.XLOOKUP(K13-7,DB!$A:$A,DB!$AG:$AG),計算用!$C$4)} -> #NAME? | T18: マルニの第2実験場 | U18: {=_xludf.XLOOKUP(T18,計算用!$R$2:$R$36,計算用!$S$2:$S$36)<>19} -> #NAME? | V18: {=_xludf.XLOOKUP(T18,計算用!$R:$R,計算用!$W:$W)} -> #NAME? | W18: {=_xludf.XLOOKUP(T18,計算用!$R:$R,計算用!$Y:$Y)} -> #NAME? | X18: {=_xludf.XLOOKUP(T18,計算用!$R:$R,計算用!$X:$X)} -> #NAME? | Y18: {=_xludf.XLOOKUP(T13,DB!$A:$A,DB!$AJ:$AJ)} -> #NAME? | Z18: {=_xludf.XLOOKUP(T13,DB!$A:$A,DB!$AK:$AK)} -> #NAME? | AA18: {=_xludf.XLOOKUP(T13,DB!$A:$A,DB!$AL:$AL)} -> #NAME? | AB18: {=IF(_xludf.IFNA(AA18=0,TRUE),_xludf.XLOOKUP(T13-7,DB!$A:$A,DB!$AG:$AG),計算用!$C$4)} -> #NAME?
B19: ナーガ沼地 | C19: {=_xludf.XLOOKUP(B19,計算用!$R$2:$R$36,計算用!$S$2:$S$36)<>19} -> #NAME? | D19: {=_xludf.XLOOKUP(B19,計算用!$R:$R,計算用!$W:$W)} -> #NAME? | E19: {=_xludf.XLOOKUP(B19,計算用!$R:$R,計算用!$Y:$Y)} -> #NAME? | F19: {=_xludf.XLOOKUP(B19,計算用!$R:$R,計算用!$X:$X)} -> #NAME? | G19: {=_xludf.XLOOKUP(B13,DB!$A:$A,DB!$AR:$AR)} -> #NAME? | H19: {=_xludf.XLOOKUP(B13,DB!$A:$A,DB!$AS:$AS)} -> #NAME? | I19: {=_xludf.XLOOKUP(B13,DB!$A:$A,DB!$AT:$AT)} -> #NAME? | J19: {=IF(_xludf.IFNA(I19=0,TRUE),_xludf.XLOOKUP(B13-7,DB!$A:$A,DB!$AO:$AO),計算用!$C$4)} -> #NAME? | K19: 隠遁の森 | L19: {=_xludf.XLOOKUP(K19,計算用!$R$2:$R$36,計算用!$S$2:$S$36)<>19} -> #NAME? | M19: {=_xludf.XLOOKUP(K19,計算用!$R:$R,計算用!$W:$W)} -> #NAME? | N19: {=_xludf.XLOOKUP(K19,計算用!$R:$R,計算用!$Y:$Y)} -> #NAME? | O19: {=_xludf.XLOOKUP(K19,計算用!$R:$R,計算用!$X:$X)} -> #NAME? | P19: {=_xludf.XLOOKUP(K13,DB!$A:$A,DB!$AR:$AR)} -> #NAME? | Q19: {=_xludf.XLOOKUP(K13,DB!$A:$A,DB!$AS:$AS)} -> #NAME? | R19: {=_xludf.XLOOKUP(K13,DB!$A:$A,DB!$AT:$AT)} -> #NAME? | S19: {=IF(_xludf.IFNA(R19=0,TRUE),_xludf.XLOOKUP(K13-7,DB!$A:$A,DB!$AO:$AO),計算用!$C$4)} -> #NAME? | T19: アグリス平原 | U19: {=_xludf.XLOOKUP(T19,計算用!$R$2:$R$36,計算用!$S$2:$S$36)<>19} -> #NAME? | V19: {=_xludf.XLOOKUP(T19,計算用!$R:$R,計算用!$W:$W)} -> #NAME? | W19: {=_xludf.XLOOKUP(T19,計算用!$R:$R,計算用!$Y:$Y)} -> #NAME? | X19: {=_xludf.XLOOKUP(T19,計算用!$R:$R,計算用!$X:$X)} -> #NAME? | Y19: {=_xludf.XLOOKUP(T13,DB!$A:$A,DB!$AR:$AR)} -> #NAME? | Z19: {=_xludf.XLOOKUP(T13,DB!$A:$A,DB!$AS:$AS)} -> #NAME? | AA19: {=_xludf.XLOOKUP(T13,DB!$A:$A,DB!$AT:$AT)} -> #NAME? | AB19: {=IF(_xludf.IFNA(AA19=0,TRUE),_xludf.XLOOKUP(T13-7,DB!$A:$A,DB!$AO:$AO),計算用!$C$4)} -> #NAME? | AC19: 北部採石場 | AD19: {=_xludf.XLOOKUP(AC19,計算用!$R$2:$R$36,計算用!$S$2:$S$36)<>19} -> #NAME? | AE19: {=_xludf.XLOOKUP(AC19,計算用!$R:$R,計算用!$W:$W)} -> #NAME? | AF19: {=_xludf.XLOOKUP(AC19,計算用!$R:$R,計算用!$Y:$Y)} -> #NAME? | AG19: {=_xludf.XLOOKUP(AC19,計算用!$R:$R,計算用!$X:$X)} -> #NAME? | AH19: {=_xludf.XLOOKUP(AC13,DB!$A:$A,DB!$AR:$AR)} -> #NAME? | AI19: {=_xludf.XLOOKUP(AC13,DB!$A:$A,DB!$AS:$AS)} -> #NAME? | AJ19: {=_xludf.XLOOKUP(AC13,DB!$A:$A,DB!$AT:$AT)} -> #NAME? | AK19: {=IF(_xludf.IFNA(AJ19=0,TRUE),_xludf.XLOOKUP(AC13-7,DB!$A:$A,DB!$AO:$AO),計算用!$C$4)} -> #NAME?
B20: 旧ダンデリオン | C20: {=_xludf.XLOOKUP(B20,計算用!$R$2:$R$36,計算用!$S$2:$S$36)<>19} -> #NAME? | D20: {=_xludf.XLOOKUP(B20,計算用!$R:$R,計算用!$W:$W)} -> #NAME? | E20: {=_xludf.XLOOKUP(B20,計算用!$R:$R,計算用!$Y:$Y)} -> #NAME? | F20: {=_xludf.XLOOKUP(B20,計算用!$R:$R,計算用!$X:$X)} -> #NAME? | G20: {=_xludf.XLOOKUP(B13,DB!$A:$A,DB!$AZ:$AZ)} -> #NAME? | H20: {=_xludf.XLOOKUP(B13,DB!$A:$A,DB!$BA:$BA)} -> #NAME? | I20: {=_xludf.XLOOKUP(B13,DB!$A:$A,DB!$BB:$BB)} -> #NAME? | J20: {=IF(_xludf.IFNA(I20=0,TRUE),_xludf.XLOOKUP(B13-7,DB!$A:$A,DB!$AW:$AW),計算用!$C$4)} -> #NAME? | K20: エワズの丘 | L20: {=_xludf.XLOOKUP(K20,計算用!$R$2:$R$36,計算用!$S$2:$S$36)<>19} -> #NAME? | M20: {=_xludf.XLOOKUP(K20,計算用!$R:$R,計算用!$W:$W)} -> #NAME? | N20: {=_xludf.XLOOKUP(K20,計算用!$R:$R,計算用!$Y:$Y)} -> #NAME? | O20: {=_xludf.XLOOKUP(K20,計算用!$R:$R,計算用!$X:$X)} -> #NAME? | P20: {=_xludf.XLOOKUP(K13,DB!$A:$A,DB!$AZ:$AZ)} -> #NAME? | Q20: {=_xludf.XLOOKUP(K13,DB!$A:$A,DB!$BA:$BA)} -> #NAME? | R20: {=_xludf.XLOOKUP(K13,DB!$A:$A,DB!$BB:$BB)} -> #NAME? | S20: {=IF(_xludf.IFNA(R20=0,TRUE),_xludf.XLOOKUP(K13-7,DB!$A:$A,DB!$AW:$AW),計算用!$C$4)} -> #NAME? | T20: リンチ農場廃墟 | U20: {=_xludf.XLOOKUP(T20,計算用!$R$2:$R$36,計算用!$S$2:$S$36)<>19} -> #NAME? | V20: {=_xludf.XLOOKUP(T20,計算用!$R:$R,計算用!$W:$W)} -> #NAME? | W20: {=_xludf.XLOOKUP(T20,計算用!$R:$R,計算用!$Y:$Y)} -> #NAME? | X20: {=_xludf.XLOOKUP(T20,計算用!$R:$R,計算用!$X:$X)} -> #NAME? | Y20: {=_xludf.XLOOKUP(T13,DB!$A:$A,DB!$AZ:$AZ)} -> #NAME? | Z20: {=_xludf.XLOOKUP(T13,DB!$A:$A,DB!$BA:$BA)} -> #NAME? | AA20: {=_xludf.XLOOKUP(T13,DB!$A:$A,DB!$BB:$BB)} -> #NAME? | AB20: {=IF(_xludf.IFNA(AA20=0,TRUE),_xludf.XLOOKUP(T13-7,DB!$A:$A,DB!$AW:$AW),計算用!$C$4)} -> #NAME? | AC20: ハーピーの絶壁 | AD20: {=_xludf.XLOOKUP(AC20,計算用!$R$2:$R$36,計算用!$S$2:$S$36)<>19} -> #NAME? | AE20: {=_xludf.XLOOKUP(AC20,計算用!$R:$R,計算用!$W:$W)} -> #NAME? | AF20: {=_xludf.XLOOKUP(AC20,計算用!$R:$R,計算用!$Y:$Y)} -> #NAME? | AG20: {=_xludf.XLOOKUP(AC20,計算用!$R:$R,計算用!$X:$X)} -> #NAME? | AH20: {=_xludf.XLOOKUP(AC13,DB!$A:$A,DB!$AZ:$AZ)} -> #NAME? | AI20: {=_xludf.XLOOKUP(AC13,DB!$A:$A,DB!$BA:$BA)} -> #NAME? | AJ20: {=_xludf.XLOOKUP(AC13,DB!$A:$A,DB!$BB:$BB)} -> #NAME? | AK20: {=IF(_xludf.IFNA(AJ20=0,TRUE),_xludf.XLOOKUP(AC13-7,DB!$A:$A,DB!$AW:$AW),計算用!$C$4)} -> #NAME?
B21: 捨てられた地 | C21: {=_xludf.XLOOKUP(B21,計算用!$R$2:$R$36,計算用!$S$2:$S$36)<>19} -> #NAME? | D21: {=_xludf.XLOOKUP(B21,計算用!$R:$R,計算用!$W:$W)} -> #NAME? | E21: {=_xludf.XLOOKUP(B21,計算用!$R:$R,計算用!$Y:$Y)} -> #NAME? | F21: {=_xludf.XLOOKUP(B21,計算用!$R:$R,計算用!$X:$X)} -> #NAME? | G21: {=_xludf.XLOOKUP(B13,DB!$A:$A,DB!$BH:$BH)} -> #NAME? | H21: {=_xludf.XLOOKUP(B13,DB!$A:$A,DB!$BI:$BI)} -> #NAME? | I21: {=_xludf.XLOOKUP(B13,DB!$A:$A,DB!$BJ:$BJ)} -> #NAME? | J21: {=IF(_xludf.IFNA(I21=0,TRUE),_xludf.XLOOKUP(B13-7,DB!$A:$A,DB!$BE:$BE),計算用!$C$4)} -> #NAME? | K21: 廃城跡入り口 | L21: {=_xludf.XLOOKUP(K21,計算用!$R$2:$R$36,計算用!$S$2:$S$36)<>19} -> #NAME? | M21: {=_xludf.XLOOKUP(K21,計算用!$R:$R,計算用!$W:$W)} -> #NAME? | N21: {=_xludf.XLOOKUP(K21,計算用!$R:$R,計算用!$Y:$Y)} -> #NAME? | O21: {=_xludf.XLOOKUP(K21,計算用!$R:$R,計算用!$X:$X)} -> #NAME? | P21: {=_xludf.XLOOKUP(K13,DB!$A:$A,DB!$BH:$BH)} -> #NAME? | Q21: {=_xludf.XLOOKUP(K13,DB!$A:$A,DB!$BI:$BI)} -> #NAME? | R21: {=_xludf.XLOOKUP(K13,DB!$A:$A,DB!$BJ:$BJ)} -> #NAME? | S21: {=IF(_xludf.IFNA(R21=0,TRUE),_xludf.XLOOKUP(K13-7,DB!$A:$A,DB!$BE:$BE),計算用!$C$4)} -> #NAME? | T21: ブレディー砦 | U21: {=_xludf.XLOOKUP(T21,計算用!$R$2:$R$36,計算用!$S$2:$S$36)<>19} -> #NAME? | V21: {=_xludf.XLOOKUP(T21,計算用!$R:$R,計算用!$W:$W)} -> #NAME? | W21: {=_xludf.XLOOKUP(T21,計算用!$R:$R,計算用!$Y:$Y)} -> #NAME? | X21: {=_xludf.XLOOKUP(T21,計算用!$R:$R,計算用!$X:$X)} -> #NAME? | Y21: {=_xludf.XLOOKUP(T13,DB!$A:$A,DB!$BH:$BH)} -> #NAME? | Z21: {=_xludf.XLOOKUP(T13,DB!$A:$A,DB!$BI:$BI)} -> #NAME? | AA21: {=_xludf.XLOOKUP(T13,DB!$A:$A,DB!$BJ:$BJ)} -> #NAME? | AB21: {=IF(_xludf.IFNA(AA21=0,TRUE),_xludf.XLOOKUP(T13-7,DB!$A:$A,DB!$BE:$BE),計算用!$C$4)} -> #NAME? | AC21: ブリの森 | AD21: {=_xludf.XLOOKUP(AC21,計算用!$R$2:$R$36,計算用!$S$2:$S$36)<>19} -> #NAME? | AE21: {=_xludf.XLOOKUP(AC21,計算用!$R:$R,計算用!$W:$W)} -> #NAME? | AF21: {=_xludf.XLOOKUP(AC21,計算用!$R:$R,計算用!$Y:$Y)} -> #NAME? | AG21: {=_xludf.XLOOKUP(AC21,計算用!$R:$R,計算用!$X:$X)} -> #NAME? | AH21: {=_xludf.XLOOKUP(AC13,DB!$A:$A,DB!$BH:$BH)} -> #NAME? | AI21: {=_xludf.XLOOKUP(AC13,DB!$A:$A,DB!$BI:$BI)} -> #NAME? | AJ21: {=_xludf.XLOOKUP(AC13,DB!$A:$A,DB!$BJ:$BJ)} -> #NAME? | AK21: {=IF(_xludf.IFNA(AJ21=0,TRUE),_xludf.XLOOKUP(AC13-7,DB!$A:$A,DB!$BE:$BE),計算用!$C$4)} -> #NAME?
B22: ベア川下流 | C22: {=_xludf.XLOOKUP(B22,計算用!$R$2:$R$36,計算用!$S$2:$S$36)<>19} -> #NAME? | D22: {=_xludf.XLOOKUP(B22,計算用!$R:$R,計算用!$W:$W)} -> #NAME? | E22: {=_xludf.XLOOKUP(B22,計算用!$R:$R,計算用!$Y:$Y)} -> #NAME? | F22: {=_xludf.XLOOKUP(B22,計算用!$R:$R,計算用!$X:$X)} -> #NAME? | G22: {=_xludf.XLOOKUP(B13,DB!$A:$A,DB!$BP:$BP)} -> #NAME? | H22: {=_xludf.XLOOKUP(B13,DB!$A:$A,DB!$BQ:$BQ)} -> #NAME? | I22: {=_xludf.XLOOKUP(B13,DB!$A:$A,DB!$BR:$BR)} -> #NAME? | J22: {=IF(_xludf.IFNA(I22=0,TRUE),_xludf.XLOOKUP(B13-7,DB!$A:$A,DB!$BM:$BM),計算用!$C$4)} -> #NAME? | K22: カイア渡し場 | L22: {=_xludf.XLOOKUP(K22,計算用!$R$2:$R$36,計算用!$S$2:$S$36)<>19} -> #NAME? | M22: {=_xludf.XLOOKUP(K22,計算用!$R:$R,計算用!$W:$W)} -> #NAME? | N22: {=_xludf.XLOOKUP(K22,計算用!$R:$R,計算用!$Y:$Y)} -> #NAME? | O22: {=_xludf.XLOOKUP(K22,計算用!$R:$R,計算用!$X:$X)} -> #NAME? | P22: {=_xludf.XLOOKUP(K13,DB!$A:$A,DB!$BP:$BP)} -> #NAME? | Q22: {=_xludf.XLOOKUP(K13,DB!$A:$A,DB!$BQ:$BQ)} -> #NAME? | R22: {=_xludf.XLOOKUP(K13,DB!$A:$A,DB!$BR:$BR)} -> #NAME? | S22: {=IF(_xludf.IFNA(R22=0,TRUE),_xludf.XLOOKUP(K13-7,DB!$A:$A,DB!$BM:$BM),計算用!$C$4)} -> #NAME? | T22: エントの森 | U22: {=_xludf.XLOOKUP(T22,計算用!$R$2:$R$36,計算用!$S$2:$S$36)<>19} -> #NAME? | V22: {=_xludf.XLOOKUP(T22,計算用!$R:$R,計算用!$W:$W)} -> #NAME? | W22: {=_xludf.XLOOKUP(T22,計算用!$R:$R,計算用!$Y:$Y)} -> #NAME? | X22: {=_xludf.XLOOKUP(T22,計算用!$R:$R,計算用!$X:$X)} -> #NAME? | Y22: {=_xludf.XLOOKUP(T13,DB!$A:$A,DB!$BP:$BP)} -> #NAME? | Z22: {=_xludf.XLOOKUP(T13,DB!$A:$A,DB!$BQ:$BQ)} -> #NAME? | AA22: {=_xludf.XLOOKUP(T13,DB!$A:$A,DB!$BR:$BR)} -> #NAME? | AB22: {=IF(_xludf.IFNA(AA22=0,TRUE),_xludf.XLOOKUP(T13-7,DB!$A:$A,DB!$BM:$BM),計算用!$C$4)} -> #NAME? | AC22: マンシャの森の奥 | AD22: {=_xludf.XLOOKUP(AC22,計算用!$R$2:$R$36,計算用!$S$2:$S$36)<>19} -> #NAME? | AE22: {=_xludf.XLOOKUP(AC22,計算用!$R:$R,計算用!$W:$W)} -> #NAME? | AF22: {=_xludf.XLOOKUP(AC22,計算用!$R:$R,計算用!$Y:$Y)} -> #NAME? | AG22: {=_xludf.XLOOKUP(AC22,計算用!$R:$R,計算用!$X:$X)} -> #NAME? | AH22: {=_xludf.XLOOKUP(AC13,DB!$A:$A,DB!$BP:$BP)} -> #NAME? | AI22: {=_xludf.XLOOKUP(AC13,DB!$A:$A,DB!$BQ:$BQ)} -> #NAME? | AJ22: {=_xludf.XLOOKUP(AC13,DB!$A:$A,DB!$BR:$BR)} -> #NAME? | AK22: {=IF(_xludf.IFNA(AJ22=0,TRUE),_xludf.XLOOKUP(AC13-7,DB!$A:$A,DB!$BM:$BM),計算用!$C$4)} -> #NAME?
B23: アルティノ入り口 | C23: {=_xludf.XLOOKUP(B23,計算用!$R$2:$R$36,計算用!$S$2:$S$36)<>19} -> #NAME? | D23: {=_xludf.XLOOKUP(B23,計算用!$R:$R,計算用!$W:$W)} -> #NAME? | E23: {=_xludf.XLOOKUP(B23,計算用!$R:$R,計算用!$Y:$Y)} -> #NAME? | F23: {=_xludf.XLOOKUP(B23,計算用!$R:$R,計算用!$X:$X)} -> #NAME? | G23: {=_xludf.XLOOKUP(B13,DB!$A:$A,DB!$BX:$BX)} -> #NAME? | H23: {=_xludf.XLOOKUP(B13,DB!$A:$A,DB!$BY:$BY)} -> #NAME? | I23: {=_xludf.XLOOKUP(B13,DB!$A:$A,DB!$BZ:$BZ)} -> #NAME? | J23: {=IF(_xludf.IFNA(I23=0,TRUE),_xludf.XLOOKUP(B13-7,DB!$A:$A,DB!$BU:$BU),計算用!$C$4)} -> #NAME? | K23: カズラ農場 | L23: {=_xludf.XLOOKUP(K23,計算用!$R$2:$R$36,計算用!$S$2:$S$36)<>19} -> #NAME? | M23: {=_xludf.XLOOKUP(K23,計算用!$R:$R,計算用!$W:$W)} -> #NAME? | N23: {=_xludf.XLOOKUP(K23,計算用!$R:$R,計算用!$Y:$Y)} -> #NAME? | O23: {=_xludf.XLOOKUP(K23,計算用!$R:$R,計算用!$X:$X)} -> #NAME? | P23: {=_xludf.XLOOKUP(K13,DB!$A:$A,DB!$BX:$BX)} -> #NAME? | Q23: {=_xludf.XLOOKUP(K13,DB!$A:$A,DB!$BY:$BY)} -> #NAME? | R23: {=_xludf.XLOOKUP(K13,DB!$A:$A,DB!$BZ:$BZ)} -> #NAME? | S23: {=IF(_xludf.IFNA(R23=0,TRUE),_xludf.XLOOKUP(K13-7,DB!$A:$A,DB!$BU:$BU),計算用!$C$4)} -> #NAME? | T23: クリオ村 | U23: {=_xludf.XLOOKUP(T23,計算用!$R$2:$R$36,計算用!$S$2:$S$36)<>19} -> #NAME? | V23: {=_xludf.XLOOKUP(T23,計算用!$R:$R,計算用!$W:$W)} -> #NAME? | W23: {=_xludf.XLOOKUP(T23,計算用!$R:$R,計算用!$Y:$Y)} -> #NAME? | X23: {=_xludf.XLOOKUP(T23,計算用!$R:$R,計算用!$X:$X)} -> #NAME? | Y23: {=_xludf.XLOOKUP(T13,DB!$A:$A,DB!$BX:$BX)} -> #NAME? | Z23: {=_xludf.XLOOKUP(T13,DB!$A:$A,DB!$BY:$BY)} -> #NAME? | AA23: {=_xludf.XLOOKUP(T13,DB!$A:$A,DB!$BZ:$BZ)} -> #NAME? | AB23: {=IF(_xludf.IFNA(AA23=0,TRUE),_xludf.XLOOKUP(T13-7,DB!$A:$A,DB!$BU:$BU),計算用!$C$4)} -> #NAME? | AC23: 廃鉄鉱山採掘場 | AD23: {=_xludf.XLOOKUP(AC23,計算用!$R$2:$R$36,計算用!$S$2:$S$36)<>19} -> #NAME? | AE23: {=_xludf.XLOOKUP(AC23,計算用!$R:$R,計算用!$W:$W)} -> #NAME? | AF23: {=_xludf.XLOOKUP(AC23,計算用!$R:$R,計算用!$Y:$Y)} -> #NAME? | AG23: {=_xludf.XLOOKUP(AC23,計算用!$R:$R,計算用!$X:$X)} -> #NAME? | AH23: {=_xludf.XLOOKUP(AC13,DB!$A:$A,DB!$BX:$BX)} -> #NAME? | AI23: {=_xludf.XLOOKUP(AC13,DB!$A:$A,DB!$BY:$BY)} -> #NAME? | AJ23: {=_xludf.XLOOKUP(AC13,DB!$A:$A,DB!$BZ:$BZ)} -> #NAME? | AK23: {=IF(_xludf.IFNA(AJ23=0,TRUE),_xludf.XLOOKUP(AC13-7,DB!$A:$A,DB!$BU:$BU),計算用!$C$4)} -> #NAME?
B24: =B13+7 -> 45900 | C24: 22時 | D24: 城塞 | E24: 枠 | F24: 人数 | G24: 統一 | H24: 宴会 | I24: 税 | J24: 保有 | K24: =B24+1 -> 45901 | L24: 22時 | M24: 種別 | N24: 枠 | O24: 人数 | P24: 統一 | Q24: 宴会 | R24: 税 | S24: 保有 | T24: =K24+3 -> 45904 | U24: 22時 | V24: 種別 | W24: 枠 | X24: 人数 | Y24: 統一 | Z24: 宴会 | AA24: 税 | AB24: 保有 | AC24: =T24+1 -> 45905 | AD24: 22時 | AE24: 種別 | AF24: 枠 | AG24: 人数 | AH24: 統一 | AI24: 宴会 | AJ24: 税 | AK24: 保有
B25: デルニール農場 | C25: {=_xludf.XLOOKUP(B25,計算用!$R$2:$R$36,計算用!$S$2:$S$36)<>19} -> #NAME? | D25: {=_xludf.XLOOKUP(B25,計算用!$R:$R,計算用!$W:$W)} -> #NAME? | E25: {=_xludf.XLOOKUP(B25,計算用!$R:$R,計算用!$Y:$Y)} -> #NAME? | F25: {=_xludf.XLOOKUP(B25,計算用!$R:$R,計算用!$X:$X)} -> #NAME? | G25: - | H25: {=_xludf.XLOOKUP(B24,DB!$A:$A,DB!$F:$F)} -> #NAME? | I25: {=_xludf.XLOOKUP(B24,DB!$A:$A,DB!$G:$G)} -> #NAME? | J25: {=IF(_xludf.IFNA(I25=0,TRUE),_xludf.XLOOKUP(B24-7,DB!$A:$A,DB!$C:$C),計算用!$C$4)} -> #NAME? | K25: ルツム族駐屯地 | L25: {=_xludf.XLOOKUP(K25,計算用!$R$2:$R$36,計算用!$S$2:$S$36)<>19} -> #NAME? | M25: {=_xludf.XLOOKUP(K25,計算用!$R:$R,計算用!$W:$W)} -> #NAME? | N25: {=_xludf.XLOOKUP(K25,計算用!$R:$R,計算用!$Y:$Y)} -> #NAME? | O25: {=_xludf.XLOOKUP(K25,計算用!$R:$R,計算用!$X:$X)} -> #NAME? | P25: - | Q25: {=_xludf.XLOOKUP(K24,DB!$A:$A,DB!$F:$F)} -> #NAME? | R25: {=_xludf.XLOOKUP(K24,DB!$A:$A,DB!$G:$G)} -> #NAME? | S25: {=IF(_xludf.IFNA(R25=0,TRUE),_xludf.XLOOKUP(K24-7,DB!$A:$A,DB!$C:$C),計算用!$C$4)} -> #NAME? | T25: 北部大農場 | U25: {=_xludf.XLOOKUP(T25,計算用!$R$2:$R$36,計算用!$S$2:$S$36)<>19} -> #NAME? | V25: {=_xludf.XLOOKUP(T25,計算用!$R:$R,計算用!$W:$W)} -> #NAME? | W25: {=_xludf.XLOOKUP(T25,計算用!$R:$R,計算用!$Y:$Y)} -> #NAME? | X25: {=_xludf.XLOOKUP(T25,計算用!$R:$R,計算用!$X:$X)} -> #NAME? | Y25: - | Z25: {=_xludf.XLOOKUP(T24,DB!$A:$A,DB!$F:$F)} -> #NAME? | AA25: {=_xludf.XLOOKUP(T24,DB!$A:$A,DB!$G:$G)} -> #NAME? | AB25: {=IF(_xludf.IFNA(AA25=0,TRUE),_xludf.XLOOKUP(T24-7,DB!$A:$A,DB!$C:$C),計算用!$C$4)} -> #NAME? | AC25: アグリス祭壇 | AD25: {=_xludf.XLOOKUP(AC25,計算用!$R$2:$R$36,計算用!$S$2:$S$36)<>19} -> #NAME? | AE25: {=_xludf.XLOOKUP(AC25,計算用!$R:$R,計算用!$W:$W)} -> #NAME? | AF25: {=_xludf.XLOOKUP(AC25,計算用!$R:$R,計算用!$Y:$Y)} -> #NAME? | AG25: {=_xludf.XLOOKUP(AC25,計算用!$R:$R,計算用!$X:$X)} -> #NAME? | AH25: - | AI25: {=_xludf.XLOOKUP(AC24,DB!$A:$A,DB!$F:$F)} -> #NAME? | AJ25: {=_xludf.XLOOKUP(AC24,DB!$A:$A,DB!$G:$G)} -> #NAME? | AK25: {=IF(_xludf.IFNA(AJ25=0,TRUE),_xludf.XLOOKUP(AC24-7,DB!$A:$A,DB!$C:$C),計算用!$C$4)} -> #NAME?
J26: {=IF(_xludf.IFNA(I26=0,TRUE),_xludf.XLOOKUP(B24-7,DB!$A:$A,DB!$J:$J),計算用!$C$4)} -> #NAME? | K26: アト農場 | L26: {=_xludf.XLOOKUP(K26,計算用!$R$2:$R$36,計算用!$S$2:$S$36)<>19} -> #NAME? | M26: {=_xludf.XLOOKUP(K26,計算用!$R:$R,計算用!$W:$W)} -> #NAME? | N26: {=_xludf.XLOOKUP(K26,計算用!$R:$R,計算用!$Y:$Y)} -> #NAME? | O26: {=_xludf.XLOOKUP(K26,計算用!$R:$R,計算用!$X:$X)} -> #NAME? | P26: - | Q26: {=_xludf.XLOOKUP(K24,DB!$A:$A,DB!$M:$M)} -> #NAME? | R26: {=_xludf.XLOOKUP(K24,DB!$A:$A,DB!$N:$N)} -> #NAME? | S26: {=IF(_xludf.IFNA(R26=0,TRUE),_xludf.XLOOKUP(K24-7,DB!$A:$A,DB!$J:$J),計算用!$C$4)} -> #NAME?
B27: 略奪の森 | C27: {=_xludf.XLOOKUP(B27,計算用!$R$2:$R$36,計算用!$S$2:$S$36)<>19} -> #NAME? | D27: {=_xludf.XLOOKUP(B27,計算用!$R:$R,計算用!$W:$W)} -> #NAME? | E27: {=_xludf.XLOOKUP(B27,計算用!$R:$R,計算用!$Y:$Y)} -> #NAME? | F27: {=_xludf.XLOOKUP(B27,計算用!$R:$R,計算用!$X:$X)} -> #NAME? | G27: {=_xludf.XLOOKUP(B24,DB!$A:$A,DB!$T:$T)} -> #NAME? | H27: {=_xludf.XLOOKUP(B24,DB!$A:$A,DB!$U:$U)} -> #NAME? | I27: {=_xludf.XLOOKUP(B24,DB!$A:$A,DB!$V:$V)} -> #NAME? | J27: {=IF(_xludf.IFNA(I27=0,TRUE),_xludf.XLOOKUP(B24-7,DB!$A:$A,DB!$Q:$Q),計算用!$C$4)} -> #NAME? | K27: ベリア農場地帯 | L27: {=_xludf.XLOOKUP(K27,計算用!$R$2:$R$36,計算用!$S$2:$S$36)<>19} -> #NAME? | M27: {=_xludf.XLOOKUP(K27,計算用!$R:$R,計算用!$W:$W)} -> #NAME? | N27: {=_xludf.XLOOKUP(K27,計算用!$R:$R,計算用!$Y:$Y)} -> #NAME? | O27: {=_xludf.XLOOKUP(K27,計算用!$R:$R,計算用!$X:$X)} -> #NAME? | P27: {=_xludf.XLOOKUP(K24,DB!$A:$A,DB!$T:$T)} -> #NAME? | Q27: {=_xludf.XLOOKUP(K24,DB!$A:$A,DB!$U:$U)} -> #NAME? | R27: {=_xludf.XLOOKUP(K24,DB!$A:$A,DB!$V:$V)} -> #NAME? | S27: {=IF(_xludf.IFNA(R27=0,TRUE),_xludf.XLOOKUP(K24-7,DB!$A:$A,DB!$Q:$Q),計算用!$C$4)} -> #NAME? | T27: トロル防御基地 | U27: {=_xludf.XLOOKUP(T27,計算用!$R$2:$R$36,計算用!$S$2:$S$36)<>19} -> #NAME? | V27: {=_xludf.XLOOKUP(T27,計算用!$R:$R,計算用!$W:$W)} -> #NAME? | W27: {=_xludf.XLOOKUP(T27,計算用!$R:$R,計算用!$Y:$Y)} -> #NAME? | X27: {=_xludf.XLOOKUP(T27,計算用!$R:$R,計算用!$X:$X)} -> #NAME? | Y27: {=_xludf.XLOOKUP(T24,DB!$A:$A,DB!$T:$T)} -> #NAME? | Z27: {=_xludf.XLOOKUP(T24,DB!$A:$A,DB!$U:$U)} -> #NAME? | AA27: {=_xludf.XLOOKUP(T24,DB!$A:$A,DB!$V:$V)} -> #NAME? | AB27: {=IF(_xludf.IFNA(AA27=0,TRUE),_xludf.XLOOKUP(T24-7,DB!$A:$A,DB!$Q:$Q),計算用!$C$4)} -> #NAME? | AC27: ナーガ抽出場 | AD27: {=_xludf.XLOOKUP(AC27,計算用!$R$2:$R$36,計算用!$S$2:$S$36)<>19} -> #NAME? | AE27: {=_xludf.XLOOKUP(AC27,計算用!$R:$R,計算用!$W:$W)} -> #NAME? | AF27: {=_xludf.XLOOKUP(AC27,計算用!$R:$R,計算用!$Y:$Y)} -> #NAME? | AG27: {=_xludf.XLOOKUP(AC27,計算用!$R:$R,計算用!$X:$X)} -> #NAME? | AH27: {=_xludf.XLOOKUP(AC24,DB!$A:$A,DB!$T:$T)} -> #NAME? | AI27: {=_xludf.XLOOKUP(AC24,DB!$A:$A,DB!$U:$U)} -> #NAME? | AJ27: {=_xludf.XLOOKUP(AC24,DB!$A:$A,DB!$V:$V)} -> #NAME? | AK27: {=IF(_xludf.IFNA(AJ27=0,TRUE),_xludf.XLOOKUP(AC24-7,DB!$A:$A,DB!$Q:$Q),計算用!$C$4)} -> #NAME?
B28: 忘却の地 | C28: {=_xludf.XLOOKUP(B28,計算用!$R$2:$R$36,計算用!$S$2:$S$36)<>19} -> #NAME? | D28: {=_xludf.XLOOKUP(B28,計算用!$R:$R,計算用!$W:$W)} -> #NAME? | E28: {=_xludf.XLOOKUP(B28,計算用!$R:$R,計算用!$Y:$Y)} -> #NAME? | F28: {=_xludf.XLOOKUP(B28,計算用!$R:$R,計算用!$X:$X)} -> #NAME? | G28: {=_xludf.XLOOKUP(B24,DB!$A:$A,DB!$AB:$AB)} -> #NAME? | H28: {=_xludf.XLOOKUP(B24,DB!$A:$A,DB!$AC:$AC)} -> #NAME? | I28: {=_xludf.XLOOKUP(B24,DB!$A:$A,DB!$AD:$AD)} -> #NAME? | J28: {=IF(_xludf.IFNA(I28=0,TRUE),_xludf.XLOOKUP(B24-7,DB!$A:$A,DB!$Y:$Y),計算用!$C$4)} -> #NAME? | K28: ギュントの丘 | L28: {=_xludf.XLOOKUP(K28,計算用!$R$2:$R$36,計算用!$S$2:$S$36)<>19} -> #NAME? | M28: {=_xludf.XLOOKUP(K28,計算用!$R:$R,計算用!$W:$W)} -> #NAME? | N28: {=_xludf.XLOOKUP(K28,計算用!$R:$R,計算用!$Y:$Y)} -> #NAME? | O28: {=_xludf.XLOOKUP(K28,計算用!$R:$R,計算用!$X:$X)} -> #NAME? | P28: {=_xludf.XLOOKUP(K24,DB!$A:$A,DB!$AB:$AB)} -> #NAME? | Q28: {=_xludf.XLOOKUP(K24,DB!$A:$A,DB!$AC:$AC)} -> #NAME? | R28: {=_xludf.XLOOKUP(K24,DB!$A:$A,DB!$AD:$AD)} -> #NAME? | S28: {=IF(_xludf.IFNA(R28=0,TRUE),_xludf.XLOOKUP(K24-7,DB!$A:$A,DB!$Y:$Y),計算用!$C$4)} -> #NAME? | T28: 隠された修道院 | U28: {=_xludf.XLOOKUP(T28,計算用!$R$2:$R$36,計算用!$S$2:$S$36)<>19} -> #NAME? | V28: {=_xludf.XLOOKUP(T28,計算用!$R:$R,計算用!$W:$W)} -> #NAME? | W28: {=_xludf.XLOOKUP(T28,計算用!$R:$R,計算用!$Y:$Y)} -> #NAME? | X28: {=_xludf.XLOOKUP(T28,計算用!$R:$R,計算用!$X:$X)} -> #NAME? | Y28: {=_xludf.XLOOKUP(T24,DB!$A:$A,DB!$AB:$AB)} -> #NAME? | Z28: {=_xludf.XLOOKUP(T24,DB!$A:$A,DB!$AC:$AC)} -> #NAME? | AA28: {=_xludf.XLOOKUP(T24,DB!$A:$A,DB!$AD:$AD)} -> #NAME? | AB28: {=IF(_xludf.IFNA(AA28=0,TRUE),_xludf.XLOOKUP(T24-7,DB!$A:$A,DB!$Y:$Y),計算用!$C$4)} -> #NAME? | AC28: オークキャンプ | AD28: {=_xludf.XLOOKUP(AC28,計算用!$R$2:$R$36,計算用!$S$2:$S$36)<>19} -> #NAME? | AE28: {=_xludf.XLOOKUP(AC28,計算用!$R:$R,計算用!$W:$W)} -> #NAME? | AF28: {=_xludf.XLOOKUP(AC28,計算用!$R:$R,計算用!$Y:$Y)} -> #NAME? | AG28: {=_xludf.XLOOKUP(AC28,計算用!$R:$R,計算用!$X:$X)} -> #NAME? | AH28: {=_xludf.XLOOKUP(AC24,DB!$A:$A,DB!$AB:$AB)} -> #NAME? | AI28: {=_xludf.XLOOKUP(AC24,DB!$A:$A,DB!$AC:$AC)} -> #NAME? | AJ28: {=_xludf.XLOOKUP(AC24,DB!$A:$A,DB!$AD:$AD)} -> #NAME? | AK28: {=IF(_xludf.IFNA(AJ28=0,TRUE),_xludf.XLOOKUP(AC24-7,DB!$A:$A,DB!$Y:$Y),計算用!$C$4)} -> #NAME?
J29: {=IF(_xludf.IFNA(I29=0,TRUE),_xludf.XLOOKUP(B24-7,DB!$A:$A,DB!$AG:$AG),計算用!$C$4)} -> #NAME? | K29: 高原地帯 | L29: {=_xludf.XLOOKUP(K29,計算用!$R$2:$R$36,計算用!$S$2:$S$36)<>19} -> #NAME? | M29: {=_xludf.XLOOKUP(K29,計算用!$R:$R,計算用!$W:$W)} -> #NAME? | N29: {=_xludf.XLOOKUP(K29,計算用!$R:$R,計算用!$Y:$Y)} -> #NAME? | O29: {=_xludf.XLOOKUP(K29,計算用!$R:$R,計算用!$X:$X)} -> #NAME? | P29: {=_xludf.XLOOKUP(K24,DB!$A:$A,DB!$AJ:$AJ)} -> #NAME? | Q29: {=_xludf.XLOOKUP(K24,DB!$A:$A,DB!$AK:$AK)} -> #NAME? | R29: {=_xludf.XLOOKUP(K24,DB!$A:$A,DB!$AL:$AL)} -> #NAME? | S29: {=IF(_xludf.IFNA(R29=0,TRUE),_xludf.XLOOKUP(K24-7,DB!$A:$A,DB!$AG:$AG),計算用!$C$4)} -> #NAME? | T29: マルニの第2実験場 | U29: {=_xludf.XLOOKUP(T29,計算用!$R$2:$R$36,計算用!$S$2:$S$36)<>19} -> #NAME? | V29: {=_xludf.XLOOKUP(T29,計算用!$R:$R,計算用!$W:$W)} -> #NAME? | W29: {=_xludf.XLOOKUP(T29,計算用!$R:$R,計算用!$Y:$Y)} -> #NAME? | X29: {=_xludf.XLOOKUP(T29,計算用!$R:$R,計算用!$X:$X)} -> #NAME? | Y29: {=_xludf.XLOOKUP(T24,DB!$A:$A,DB!$AJ:$AJ)} -> #NAME? | Z29: {=_xludf.XLOOKUP(T24,DB!$A:$A,DB!$AK:$AK)} -> #NAME? | AA29: {=_xludf.XLOOKUP(T24,DB!$A:$A,DB!$AL:$AL)} -> #NAME? | AB29: {=IF(_xludf.IFNA(AA29=0,TRUE),_xludf.XLOOKUP(T24-7,DB!$A:$A,DB!$AG:$AG),計算用!$C$4)} -> #NAME?
B30: ナーガ沼地 | C30: {=_xludf.XLOOKUP(B30,計算用!$R$2:$R$36,計算用!$S$2:$S$36)<>19} -> #NAME? | D30: {=_xludf.XLOOKUP(B30,計算用!$R:$R,計算用!$W:$W)} -> #NAME? | E30: {=_xludf.XLOOKUP(B30,計算用!$R:$R,計算用!$Y:$Y)} -> #NAME? | F30: {=_xludf.XLOOKUP(B30,計算用!$R:$R,計算用!$X:$X)} -> #NAME? | G30: {=_xludf.XLOOKUP(B24,DB!$A:$A,DB!$AR:$AR)} -> #NAME? | H30: {=_xludf.XLOOKUP(B24,DB!$A:$A,DB!$AS:$AS)} -> #NAME? | I30: {=_xludf.XLOOKUP(B24,DB!$A:$A,DB!$AT:$AT)} -> #NAME? | J30: {=IF(_xludf.IFNA(I30=0,TRUE),_xludf.XLOOKUP(B24-7,DB!$A:$A,DB!$AO:$AO),計算用!$C$4)} -> #NAME? | K30: 隠遁の森 | L30: {=_xludf.XLOOKUP(K30,計算用!$R$2:$R$36,計算用!$S$2:$S$36)<>19} -> #NAME? | M30: {=_xludf.XLOOKUP(K30,計算用!$R:$R,計算用!$W:$W)} -> #NAME? | N30: {=_xludf.XLOOKUP(K30,計算用!$R:$R,計算用!$Y:$Y)} -> #NAME? | O30: {=_xludf.XLOOKUP(K30,計算用!$R:$R,計算用!$X:$X)} -> #NAME? | P30: {=_xludf.XLOOKUP(K24,DB!$A:$A,DB!$AR:$AR)} -> #NAME? | Q30: {=_xludf.XLOOKUP(K24,DB!$A:$A,DB!$AS:$AS)} -> #NAME? | R30: {=_xludf.XLOOKUP(K24,DB!$A:$A,DB!$AT:$AT)} -> #NAME? | S30: {=IF(_xludf.IFNA(R30=0,TRUE),_xludf.XLOOKUP(K24-7,DB!$A:$A,DB!$AO:$AO),計算用!$C$4)} -> #NAME? | T30: アグリス平原 | U30: {=_xludf.XLOOKUP(T30,計算用!$R$2:$R$36,計算用!$S$2:$S$36)<>19} -> #NAME? | V30: {=_xludf.XLOOKUP(T30,計算用!$R:$R,計算用!$W:$W)} -> #NAME? | W30: {=_xludf.XLOOKUP(T30,計算用!$R:$R,計算用!$Y:$Y)} -> #NAME? | X30: {=_xludf.XLOOKUP(T30,計算用!$R:$R,計算用!$X:$X)} -> #NAME? | Y30: {=_xludf.XLOOKUP(T24,DB!$A:$A,DB!$AR:$AR)} -> #NAME? | Z30: {=_xludf.XLOOKUP(T24,DB!$A:$A,DB!$AS:$AS)} -> #NAME? | AA30: {=_xludf.XLOOKUP(T24,DB!$A:$A,DB!$AT:$AT)} -> #NAME? | AB30: {=IF(_xludf.IFNA(AA30=0,TRUE),_xludf.XLOOKUP(T24-7,DB!$A:$A,DB!$AO:$AO),計算用!$C$4)} -> #NAME? | AC30: 北部採石場 | AD30: {=_xludf.XLOOKUP(AC30,計算用!$R$2:$R$36,計算用!$S$2:$S$36)<>19} -> #NAME? | AE30: {=_xludf.XLOOKUP(AC30,計算用!$R:$R,計算用!$W:$W)} -> #NAME? | AF30: {=_xludf.XLOOKUP(AC30,計算用!$R:$R,計算用!$Y:$Y)} -> #NAME? | AG30: {=_xludf.XLOOKUP(AC30,計算用!$R:$R,計算用!$X:$X)} -> #NAME? | AH30: {=_xludf.XLOOKUP(AC24,DB!$A:$A,DB!$AR:$AR)} -> #NAME? | AI30: {=_xludf.XLOOKUP(AC24,DB!$A:$A,DB!$AS:$AS)} -> #NAME? | AJ30: {=_xludf.XLOOKUP(AC24,DB!$A:$A,DB!$AT:$AT)} -> #NAME? | AK30: {=IF(_xludf.IFNA(AJ30=0,TRUE),_xludf.XLOOKUP(AC24-7,DB!$A:$A,DB!$AO:$AO),計算用!$C$4)} -> #NAME?
B31: 旧ダンデリオン | C31: {=_xludf.XLOOKUP(B31,計算用!$R$2:$R$36,計算用!$S$2:$S$36)<>19} -> #NAME? | D31: {=_xludf.XLOOKUP(B31,計算用!$R:$R,計算用!$W:$W)} -> #NAME? | E31: {=_xludf.XLOOKUP(B31,計算用!$R:$R,計算用!$Y:$Y)} -> #NAME? | F31: {=_xludf.XLOOKUP(B31,計算用!$R:$R,計算用!$X:$X)} -> #NAME? | G31: {=_xludf.XLOOKUP(B24,DB!$A:$A,DB!$AZ:$AZ)} -> #NAME? | H31: {=_xludf.XLOOKUP(B24,DB!$A:$A,DB!$BA:$BA)} -> #NAME? | I31: {=_xludf.XLOOKUP(B24,DB!$A:$A,DB!$BB:$BB)} -> #NAME? | J31: {=IF(_xludf.IFNA(I31=0,TRUE),_xludf.XLOOKUP(B24-7,DB!$A:$A,DB!$AW:$AW),計算用!$C$4)} -> #NAME? | K31: エワズの丘 | L31: {=_xludf.XLOOKUP(K31,計算用!$R$2:$R$36,計算用!$S$2:$S$36)<>19} -> #NAME? | M31: {=_xludf.XLOOKUP(K31,計算用!$R:$R,計算用!$W:$W)} -> #NAME? | N31: {=_xludf.XLOOKUP(K31,計算用!$R:$R,計算用!$Y:$Y)} -> #NAME? | O31: {=_xludf.XLOOKUP(K31,計算用!$R:$R,計算用!$X:$X)} -> #NAME? | P31: {=_xludf.XLOOKUP(K24,DB!$A:$A,DB!$AZ:$AZ)} -> #NAME? | Q31: {=_xludf.XLOOKUP(K24,DB!$A:$A,DB!$BA:$BA)} -> #NAME? | R31: {=_xludf.XLOOKUP(K24,DB!$A:$A,DB!$BB:$BB)} -> #NAME? | S31: {=IF(_xludf.IFNA(R31=0,TRUE),_xludf.XLOOKUP(K24-7,DB!$A:$A,DB!$AW:$AW),計算用!$C$4)} -> #NAME? | T31: リンチ農場廃墟 | U31: {=_xludf.XLOOKUP(T31,計算用!$R$2:$R$36,計算用!$S$2:$S$36)<>19} -> #NAME? | V31: {=_xludf.XLOOKUP(T31,計算用!$R:$R,計算用!$W:$W)} -> #NAME? | W31: {=_xludf.XLOOKUP(T31,計算用!$R:$R,計算用!$Y:$Y)} -> #NAME? | X31: {=_xludf.XLOOKUP(T31,計算用!$R:$R,計算用!$X:$X)} -> #NAME? | Y31: {=_xludf.XLOOKUP(T24,DB!$A:$A,DB!$AZ:$AZ)} -> #NAME? | Z31: {=_xludf.XLOOKUP(T24,DB!$A:$A,DB!$BA:$BA)} -> #NAME? | AA31: {=_xludf.XLOOKUP(T24,DB!$A:$A,DB!$BB:$BB)} -> #NAME? | AB31: {=IF(_xludf.IFNA(AA31=0,TRUE),_xludf.XLOOKUP(T24-7,DB!$A:$A,DB!$AW:$AW),計算用!$C$4)} -> #NAME? | AC31: ハーピーの絶壁 | AD31: {=_xludf.XLOOKUP(AC31,計算用!$R$2:$R$36,計算用!$S$2:$S$36)<>19} -> #NAME? | AE31: {=_xludf.XLOOKUP(AC31,計算用!$R:$R,計算用!$W:$W)} -> #NAME? | AF31: {=_xludf.XLOOKUP(AC31,計算用!$R:$R,計算用!$Y:$Y)} -> #NAME? | AG31: {=_xludf.XLOOKUP(AC31,計算用!$R:$R,計算用!$X:$X)} -> #NAME? | AH31: {=_xludf.XLOOKUP(AC24,DB!$A:$A,DB!$AZ:$AZ)} -> #NAME? | AI31: {=_xludf.XLOOKUP(AC24,DB!$A:$A,DB!$BA:$BA)} -> #NAME? | AJ31: {=_xludf.XLOOKUP(AC24,DB!$A:$A,DB!$BB:$BB)} -> #NAME? | AK31: {=IF(_xludf.IFNA(AJ31=0,TRUE),_xludf.XLOOKUP(AC24-7,DB!$A:$A,DB!$AW:$AW),計算用!$C$4)} -> #NAME?
